Workbook

Sheet Risk_Inputs
A1: Date | B1: Intercept | C1: IV | D1: RV10 | E1: RV20 | F1: VRP10 | G1: VRP20 | H1: SPREAD20 | I1: RV_TREND | J1: IV_Ratio | K1: Str_Ratio | L1: Norm_OG | M1: Adj_IV_Chg | N1: Fixed_IDV | O1: u_range_bps | P1: str_range_pct | Q1: str_chg_abs | R1: spread_pct | S1: CW Stage=09:17 | T1: CW Stage=09:18 | U1: CW Stage=09:19 | V1: CW Stage=09:20+ | W1: CW DTE=2.0 | X1: CW DTE=3.0 | Y1: CW DTE=4.0 | Z1: CW DTE=5.0 | AA1: CW Weekday=1 | AB1: CW Weekday=2 | AC1: CW Weekday=3 | AD1: CW Weekday=4 | AE1: CW Weekday=5 | AF1: CW Weekday=6 | AG1: CW Event | AH1: NW | AI1: Prev_flat_DD | AJ1: Prev_flat_loss_streak
A2: 2021-01-01 | B2: 1 | C2: 0.18718514 | D2: 0.94760849 | E2: 0.039149468 | F2: -1.0050402 | G2: -0.092877302 | H2: 0.14982471 | I2: -1.0717408 | J2: 1.6719678 | K2: -0.25362685 | L2: 0.42048401 | M2: -0.77790542 | N2: -0.5932807 | O2: -0.58013725 | P2: -0.64546399 | Q2: -0.43823592 | R2: 0.43592499 | S2: 1 | T2: 0 | U2: 0 | V2: 0 | W2: 0 | X2: 0 | Y2: 0 | Z2: 1 | AA2: 0 | AB2: 0 | AC2: 0 | AD2: 1 | AE2: 0 | AF2: 0 | AG2: 0 | AH2: 0 | AI2: 0 | AJ2: 0
A3: 2021-01-04 | B3: 1 | C3: 0.4213145 | D3: 0.94521197 | E3: 0.037238942 | F3: -0.8698864 | G3: 0.13092832 | H3: 0.39282174 | I3: -1.4325015 | J3: 3 | K3: -0.73713791 | L3: 1.0636738 | M3: -1.4118135 | N3: -1.0186274 | O3: 2.1394967 | P3: -0.26214813 | Q3: 0.011743564 | R3: 0.53527339 | S3: 0 | T3: 0 | U3: 0 | V3: 1 | W3: 0 | X3: 0 | Y3: 1 | Z3: 0 | AA3: 0 | AB3: 0 | AC3: 0 | AD3: 0 | AE3: 0 | AF3: 0 | AG3: 0 | AH3: 0 | AI3: 0 | AJ3: 0
A4: 2021-01-05 | B4: 1 | C4: -0.017580683 | D4: 0.97100109 | E4: 0.027836102 | F4: -1.1354633 | G4: -0.27336135 | H4: -0.04850793 | I4: -1.684403 | J4: -0.56133784 | K4: -0.90046638 | L4: -0.60832159 | M4: -1.005994 | N4: 0.2841252 | O4: -0.43226081 | P4: -0.24811971 | Q4: 0.048974769 | R4: 0.97268922 | S4: 1 | T4: 0 | U4: 0 | V4: 0 | W4: 0 | X4: 1 | Y4: 0 | Z4: 0 | AA4: 1 | AB4: 0 | AC4: 0 | AD4: 0 | AE4: 0 | AF4: 0 | AG4: 0 | AH4: 0 | AI4: 0 | AJ4: 0
A5: 2021-01-06 | B5: 1 | C5: 0.039521971 | D5: -1.1307143 | E5: 0.019571149 | F5: 2.7347344 | G5: -0.20936183 | H5: 0.019279901 | I5: -1.6720652 | J5: 0.52653827 | K5: -0.24048233 | L5: 0.30957935 | M5: 1.161994 | N5: -0.25998975 | O5: -0.36223045 | P5: -0.61115944 | Q5: -0.33020527 | R5: 0.44812766 | S5: 1 | T5: 0 | U5: 0 | V5: 0 | W5: 1 | X5: 0 | Y5: 0 | Z5: 0 | AA5: 0 | AB5: 1 | AC5: 0 | AD5: 0 | AE5: 0 | AF5: 0 | AG5: 0 | AH5: 0 | AI5: 0.14245693 | AJ5: 0.33333333
A6: 2021-01-07 | B6: 1 | C6: -0.66124481 | D6: -1.0464756 | E6: 0.036949141 | F6: 1.1588054 | G6: -0.89280935 | H6: -0.72076962 | I6: -1.4375015 | J6: -1.6152319 | K6: 3 | L6: 0.98253858 | M6: 1.2872282 | N6: 0.30035824 | O6: -0.66219979 | P6: -0.40051294 | Q6: -0.47320354 | R6: 0.39961899 | S6: 0 | T6: 1 | U6: 0 | V6: 0 | W6: 0 | X6: 0 | Y6: 0 | Z6: 0 | AA6: 0 | AB6: 0 | AC6: 1 | AD6: 0 | AE6: 0 | AF6: 0 | AG6: 0 | AH6: 0 | AI6: 0.74654689 | AJ6: 0.66666667
A7: 2021-01-11 | B7: 1 | C7: 0.15232608 | D7: -1.0379561 | E7: 0.042482068 | F7: 2.4350316 | G7: -0.12985861 | H7: 0.11031448 | I7: -0.90054156 | J7: 0.71727518 | K7: -0.19795133 | L7: 1.0745783 | M7: -0.84480991 | N7: -0.24868827 | O7: -0.28004971 | P7: -0.39417293 | Q7: -0.17310025 | R7: -0.0010337041 | S7: 0 | T7: 0 | U7: 1 | V7: 0 | W7: 0 | X7: 0 | Y7: 1 | Z7: 0 | AA7: 0 | AB7: 0 | AC7: 0 | AD7: 0 | AE7: 0 | AF7: 0 | AG7: 0 | AH7: 0 | AI7: 0.20748762 | AJ7: 0
A8: 2021-01-12 | B8: 1 | C8: 0.29834864 | D8: -1.0647775 | E8: 0.05943708 | F8: 2.8107897 | G8: -0.013258176 | H8: 0.24203782 | I8: -0.84636081 | J8: 0.24550697 | K8: -0.35500301 | L8: -0.089688685 | M8: 0.29647818 | N8: 0.11295913 | O8: -0.63507095 | P8: -0.59405986 | Q8: -0.3432021 | R8: 0.42416802 | S8: 1 | T8: 0 | U8: 0 | V8: 0 | W8: 0 | X8: 1 | Y8: 0 | Z8: 0 | AA8: 1 | AB8: 0 | AC8: 0 | AD8: 0 | AE8: 0 | AF8: 0 | AG8: 0 | AH8: 0 | AI8: 0.71311177 | AJ8: 0.33333333
A9: 2021-01-13 | B9: 1 | C9: -0.10015267 | D9: -1.0311521 | E9: 0.072387111 | F9: 1.9983806 | G9: -0.40122041 | H9: -0.18215454 | I9: -0.81908595 | J9: 0.97149195 | K9: 0.60590011 | L9: 0.5400705 | M9: -0.086137758 | N9: -0.5645133 | O9: -0.80595558 | P9: -0.42347662 | Q9: -0.55533119 | R9: 0.49836622 | S9: 1 | T9: 0 | U9: 0 | V9: 0 | W9: 1 | X9: 0 | Y9: 0 | Z9: 0 | AA9: 0 | AB9: 1 | AC9: 0 | AD9: 0 | AE9: 0 | AF9: 0 | AG9: 0 | AH9: 0 | AI9: 0.46717269 | AJ9: 0
A10: 2021-01-14 | B10: 1 | C10: -0.50074395 | D10: -0.99968788 | E10: 0.074897006 | F10: 1.2389421 | G10: -0.77747164 | H10: -0.59708884 | I10: -1.0300787 | J10: -1.0018753 | K10: 0.54277591 | L10: -0.17494 | M10: -1.4548652 | N10: 0.040218691 | O10: -0.61020694 | P10: -0.31813007 | Q10: -0.26178147 | R10: 1.6619456 | S10: 1 | T10: 0 | U10: 0 | V10: 0 | W10: 0 | X10: 0 | Y10: 0 | Z10: 0 | AA10: 0 | AB10: 0 | AC10: 1 | AD10: 0 | AE10: 0 | AF10: 0 | AG10: 0 | AH10: 0 | AI10: 0.18321027 | AJ10: 0
A11: 2021-01-15 | B11: 1 | C11: 0.18964253 | D11: -1.0585658 | E11: 0.063015129 | F11: 2.5993652 | G11: -0.11952356 | H11: 0.12627385 | I11: -1.1342126 | J11: 1.2807866 | K11: -0.42911214 | L11: -0.26668138 | M11: -0.5199406 | N11: -0.45047108 | O11: 0.096250757 | P11: -0.58678842 | Q11: -0.50915038 | R11: 0.63409106 | S11: 1 | T11: 0 | U11: 0 | V11: 0 | W11: 0 | X11: 0 | Y11: 0 | Z11: 1 | AA11: 0 | AB11: 0 | AC11: 0 | AD11: 1 | AE11: 0 | AF11: 0 | AG11: 0 | AH11: 0 | AI11: 0 | AJ11: 0
A12: 2021-01-18 | B12: 1 | C12: 1.2503377 | D12: -0.49719404 | E12: 0.22307041 | F12: 1.8393936 | G12: 0.63542223 | H12: 1.0427828 | I12: -0.32497338 | J12: 0.11801854 | K12: -0.37828597 | L12: -0.25608891 | M12: 1.7678678 | N12: 1.0787221 | O12: -0.71998534 | P12: -0.69446716 | Q12: -0.5809523 | R12: -0.091305086 | S12: 0 | T12: 1 | U12: 0 | V12: 0 | W12: 0 | X12: 0 | Y12: 1 | Z12: 0 | AA12: 0 | AB12: 0 | AC12: 0 | AD12: 0 | AE12: 0 | AF12: 0 | AG12: 0 | AH12: 0 | AI12: 0.60178525 | AJ12: 0.33333333
A13: 2021-01-19 | B13: 1 | C13: 0.6793239 | D13: -0.23961241 | E13: 0.34732154 | F13: 0.65946653 | G13: -0.014239261 | H13: 0.31945707 | I13: -0.33196196 | J13: -0.68033172 | K13: 0.4101082 | L13: 1.0504165 | M13: -0.30550835 | N13: 1.1253664 | O13: -0.26075248 | P13: 0.017957625 | Q13: -0.17448046 | R13: 2.4712854 | S13: 0 | T13: 0 | U13: 0 | V13: 0 | W13: 0 | X13: 1 | Y13: 0 | Z13: 0 | AA13: 1 | AB13: 0 | AC13: 0 | AD13: 0 | AE13: 0 | AF13: 0 | AG13: 0 | AH13: 0 | AI13: 0.44873718 | AJ13: 0
... A800: 2026-10-13 | B800: 1 | C800: -0.28020812 | D800: 0.29353485 | E800: -0.20312557 | F800: -0.82475473 | G800: -0.25301037 | H800: -0.066355124 | I800: 1.5123442 | J800: -0.6943052 | K800: -0.056649271 | L800: 0.14234687 | M800: 0.62552895 | N800: 0.08727395 | O800: -0.31918533 | P800: -0.33517661 | Q800: -0.30094485 | R800: -0.24881362 | S800: 1 | T800: 0 | U800: 0 | V800: 0 | W800: 0 | X800: 0 | Y800: 0 | Z800: 0 | AA800: 1 | AB800: 0 | AC800: 0 | AD800: 0 | AE800: 0 | AF800: 0 | AG800: 0 | AH800: 0 | AI800: 0.95973597 | AJ800: 0

Sheet Risk_Coefs
A1: Model | B1: Intercept | C1: IV | D1: RV10 | E1: RV20 | F1: VRP10 | G1: VRP20 | H1: SPREAD20 | I1: RV_TREND | J1: IV_Ratio | K1: Str_Ratio | L1: Norm_OG | M1: Adj_IV_Chg | N1: Fixed_IDV | O1: u_range_bps | P1: str_range_pct | Q1: str_chg_abs | R1: spread_pct | S1: CW Stage=09:17 | T1: CW Stage=09:18 | U1: CW Stage=09:19 | V1: CW Stage=09:20+ | W1: CW DTE=2.0 | X1: CW DTE=3.0 | Y1: CW DTE=4.0 | Z1: CW DTE=5.0 | AA1: CW Weekday=1 | AB1: CW Weekday=2 | AC1: CW Weekday=3 | AD1: CW Weekday=4 | AE1: CW Weekday=5 | AF1: CW Weekday=6 | AG1: CW Event | AH1: NW | AI1: Prev_flat_DD | AJ1: Prev_flat_loss_streak
A2: Logistic | B2: -0.825285 | C2: 0.050052271 | D2: 0.043475306 | E2: 0.11199904 | F2: 0.10016707 | G2: 0.091166772 | H2: -0.016447586 | I2: 0.067826429 | J2: 0.042447783 | K2: -0.023891896 | L2: 0.01413694 | M2: 0.012858494 | N2: -0.029499704 | O2: -0.15560095 | P2: -0.084096632 | Q2: -0.11511118 | R2: -0.11388731 | S2: -0.11255641 | T2: 0.022458537 | U2: -0.0075626854 | V2: 0.18458601 | W2: 0.0027184808 | X2: -0.1598374 | Y2: -0.0082355465 | Z2: -0.24094798 | AA2: -0.067528763 | AB2: -0.011447837 | AC2: 0.17494556 | AD2: -0.11277511 | AE2: 0.0075608231 | AF2: 0.023146783 | AG2: 0.046548159 | AH2: 0.167332 | AI2: -0.1304963 | AJ2: 0.0071564013
A3: Downside | B3: 8.9258375 | C3: 0.84123462 | D3: 1.1260159 | E3: 0.73811106 | F3: 0.96900885 | G3: 1.2820613 | H3: 0.1121499 | I3: 0.33149545 | J3: 0.0053762573 | K3: -0.15083915 | L3: 1.1129773 | M3: 0.50988288 | N3: -1.0223048 | O3: -0.51833687 | P3: -0.52489903 | Q3: -0.77538854 | R3: -0.53940361 | S3: -0.31224646 | T3: -1.0022299 | U3: 0.32000388 | V3: 2.3929591 | W3: -0.37432944 | X3: -1.7825546 | Y3: -1.0906223 | Z3: -1.8918557 | AA3: -1.1385839 | AB3: 0.14007409 | AC3: 2.0511637 | AD3: 0.18068036 | AE3: -0.12158081 | AF3: -0.020436761 | AG3: -2.1693747 | AH3: 1.5039026 | AI3: -1.5177996 | AJ3: 0.83974704

Sheet Risk_Rank_Keys
A1: Date | B1: U_order_key | C1: Straddle_order_key | D1: Spread_order_key | E1: U_raw_17digits | F1: Straddle_raw_17digits | G1: Spread_raw_17digits
A2: 2021-01-01 | B2: 210 | C2: 87 | D2: 541 | E2: 6.7846238997304011 | F2: 1.4535454724022965 | G2: 0.31428010214103208
A3: 2021-01-04 | B3: 683 | C3: 396 | D3: 563 | E3: 39.395248997260289 | F3: 3.6389083275017535 | G3: 0.3265686960578506
A4: 2021-01-05 | B4: 304 | C4: 403 | D4: 617 | E4: 8.5577827885583311 | F4: 3.7188872620790758 | G4: 0.38067349926793892
A5: 2021-01-06 | B5: 336 | C5: 125 | D5: 546 | E5: 9.3975038540327365 | F5: 1.6491228070175601 | G5: 0.31578947368421251
A6: 2021-01-07 | B6: 150 | C6: 322 | D6: 539 | E6: 5.8006271708420538 | F6: 2.8500619578686459 | G6: 0.30978934324658791
A7: 2021-01-11 | B7: 377 | C7: 327 | D7: 452 | E7: 10.382917842991466 | F7: 2.8862077123255241 | G7: 0.260231842914602
A8: 2021-01-12 | B8: 167 | C8: 144 | D8: 540 | E8: 6.1259240800733474 | F8: 1.7466110531803931 | G8: 0.31282586027112019
A9: 2021-01-13 | B9: 54 | C9: 306 | D9: 557 | E9: 4.0768782760634004 | F9: 2.7191413237924742 | G9: 0.3220035778175333
A10: 2021-01-14 | B10: 193 | C10: 366 | D10: 666 | E10: 6.4240637871747959 | F10: 3.3197437390797999 | G10: 0.46592894583575839
A11: 2021-01-15 | B11: 505 | C11: 151 | D11: 579 | E11: 14.895066822351504 | F11: 1.7880670054583101 | G11: 0.33879164313947141
A12: 2021-01-18 | B12: 100 | C12: 45 | D12: 414 | E12: 5.10773143756479 | F12: 1.1741682974559726 | G12: 0.2490660024906661
A13: 2021-01-19 | B13: 383 | C13: 505 | D13: 690 | E13: 10.614307390343289 | F13: 5.2358490566037839 | G13: 0.56603773584906458
A14: 2021-01-20 | B14: 295 | C14: 575 | D14: 671 | E14: 8.4278745932260524 | F14: 7.4086603518268044 | G14: 0.47361299052773248
A15: 2021-01-21
A16: 2021-01-22 | B16: 253 | C16: 123 | D16: 510 | E16: 7.4583317507392879 | F16: 1.6354746248524583 | G16: 0.28662957342775058
A17: 2021-01-25 | B17: 531 | C17: 235 | D17: 554 | E17: 16.728850325378602 | F17: 2.268620758883749 | G17: 0.32122063842601772
A18: 2021-01-27 | B18: 675 | C18: 627 | D18: 713 | E18: 37.435211680069074 | F18: 9.6825396825396712 | G18: 1.3756613756613727
A19: 2021-01-28 | B19: 610 | C19: 481 | D19: 663 | E19: 24.560100115768659 | F19: 4.7879616963064295 | G19: 0.4559963520291837
A20: 2021-01-29 | B20: 710 | C20: 590 | D20: 556 | E20: 59.808182765185535 | F20: 8.0519182173213899 | G20: 0.32161727544222501
A21: 2021-02-01 | B21: 405 | C21: 119 | D21: 660 | E21: 11.383308360368233 | F21: 1.623073330219521 | G21: 0.45539467538533129
A22: 2021-02-03 | B22: 669 | C22: 350 | D22: 700 | E22: 35.667553800269026 | F22: 3.1544136352073204 | G22: 0.6359704909692262
A23: 2021-02-04 | B23: 624 | C23: 649 | D23: 621 | E23: 26.100975816715422 | F23: 12.252811167119049 | G23: 0.387747188832892
A24: 2021-02-05 | B24: 553 | C24: 603 | D24: 699 | E24: 18.371403521688112 | F24: 8.5873433390066527 | G24: 0.61890762803651556
A25: 2021-02-08 | B25: 635 | C25: 534 | D25: 684 | E25: 27.113598001036213 | F25: 6.0065213660545922 | G25: 0.5148446885189536
A26: 2021-02-09 | B26: 457 | C26: 619 | D26: 633 | E26: 12.9522550801258 | F26: 9.4184027777777715 | G26: 0.41232638888889012
A27: 2021-02-10
A28: 2021-02-11 | B28: 370 | C28: 482 | D28: 619 | E28: 10.214775606584974 | F28: 4.7881355932203444 | G28: 0.3813559322034043
A29: 2021-02-12 | B29: 156 | C29: 85 | D29: 680 | E29: 5.8863571341654763 | F29: 1.4448257178977786 | G29: 0.50568900126421423
A30: 2021-02-16 | B30: 240 | C30: 241 | D30: 530 | E30: 7.2777366239104371 | F30: 2.2838499184339405 | G30: 0.29907558455682282
A31: 2021-02-17 | B31: 329 | C31: 252 | D31: 673 | E31: 9.2322500171879405 | F31: 2.3499523658304518 | G31: 0.47634169577643698
A32: 2021-02-18 | B32: 468 | C32: 475 | D32: 650 | E32: 13.27776828322448 | F32: 4.6783625730994132 | G32: 0.4385964912280661
A33: 2021-02-19 | B33: 612 | C33: 422 | D33: 711 | E33: 24.591662097271204 | F33: 3.9421587192287793 | G33: 0.91237734549836658
A34: 2021-02-22 | B34: 605 | C34: 460 | D34: 698 | E34: 23.928002112081369 | F34: 4.4529019980970457 | G34: 0.60894386298763414
A35: 2021-02-23 | B35: 338 | C35: 132 | D35: 640 | E35: 9.4079469882634328 | F35: 1.6845651716150771 | G35: 0.42114129290376928
A36: 2021-02-24 | B36: 552 | C36: 635 | D36: 654 | E36: 18.363758562400179 | F36: 10.077734591893396 | G36: 0.44419766796224941
A37: 2021-02-25 | B37: 650 | C37: 699 | D37: 667 | E37: 30.73736591692688 | F37: 23.69158878504674 | G37: 0.46728971962616161
A38: 2021-02-26 | B38: 562 | C38: 377 | D38: 629 | E38: 19.738240563602684 | F38: 3.4904493610004241 | G38: 0.39851587192524851
A39: 2021-03-02 | B39: 571 | C39: 560 | D39: 636 | E39: 20.563695117051477 | F39: 6.883468834688351 | G39: 0.41553748870822238
A40: 2021-03-03
...

Sheet Risk_Excel_Formulas
A1: Date | B1: Leg | C1: Net_PnL | D1: Logit_formula | E1: Probability_formula | F1: Downside_raw_formula | G1: Downside_formula | H1: Loss_rank_formula | I1: Downside_rank_formula | J1: U_range | K1: Str_range | L1: Spread | M1: U_rank_formula | N1: Str_rank_formula | O1: Spread_rank_formula | P1: Instability_formula | Q1: Risk_formula | R1: Threshold_formula | S1: Dicey_formula | T1: Saved_probability | U1: Saved_downside | V1: Saved_risk | W1: Risk_error_formula
A2: 2021-01-01 | B2: CW | C2: 34.787837 | D2: =SUMPRODUCT(Risk_Inputs!B2:AJ2,Risk_Coefs!$B$2:$AJ$2) -> -1.185084 | E2: =1/(1+EXP(-MAX(-25,MIN(25,D2)))) -> 0.23413931 | F2: =SUMPRODUCT(Risk_Inputs!B2:AJ2,Risk_Coefs!$B$3:$AJ$3) -> 8.1936412 | G2: =MAX(0,F2) -> 8.1936412 | H2: =(SUMPRODUCT(--ISNUMBER($E$2:$E$800),--($E$2:$E$800<E2))+(SUMPRODUCT(--ISNUMBER($E$2:$E$800),--($E$2:$E$800=E2))+1)/2)/COUNT($E$2:$E$800) -> 0.19524406 | I2: =(SUMPRODUCT(--ISNUMBER($G$2:$G$800),--($G$2:$G$800<G2))+(SUMPRODUCT(--ISNUMBER($G$2:$G$800),--($G$2:$G$800=G2))+1)/2)/COUNT($G$2:$G$800) -> 0.56195244 | J2: 6.7846239 | K2: 1.4535455 | L2: 0.3142801 | M2: =IF(OR(B2="NW",COUNT(Risk_Rank_Keys!B2)=0),0.5,(SUMPRODUCT(--ISNUMBER(Risk_Rank_Keys!$B$2:$B$800),--(Risk_Rank_Keys!$B$2:$B$800<Risk_Rank_Keys!B2))+(SUMPRODUCT(--ISNUMBER(Risk_Rank_Keys!$B$2:$B$800),--(Risk_Rank_Keys!$B$2:$B$800=Risk_Rank_Keys!B2))+1)/2)/COUNT(Risk_Rank_Keys!$B$2:$B$800)) -> 0.29288703 | N2: =IF(OR(B2="NW",COUNT(Risk_Rank_Keys!C2)=0),0.5,(SUMPRODUCT(--ISNUMBER(Risk_Rank_Keys!$C$2:$C$800),--(Risk_Rank_Keys!$C$2:$C$800<Risk_Rank_Keys!C2))+(SUMPRODUCT(--ISNUMBER(Risk_Rank_Keys!$C$2:$C$800),--(Risk_Rank_Keys!$C$2:$C$800=Risk_Rank_Keys!C2))+1)/2)/COUNT(Risk_Rank_Keys!$C$2:$C$800)) -> 0.12133891 | O2: =IF(OR(B2="NW",COUNT(Risk_Rank_Keys!D2)=0),0.5,(SUMPRODUCT(--ISNUMBER(Risk_Rank_Keys!$D$2:$D$800),--(Risk_Rank_Keys!$D$2:$D$800<Risk_Rank_Keys!D2))+(SUMPRODUCT(--ISNUMBER(Risk_Rank_Keys!$D$2:$D$800),--(Risk_Rank_Keys!$D$2:$D$800=Risk_Rank_Keys!D2))+1)/2)/COUNT(Risk_Rank_Keys!$D$2:$D$800)) -> 0.76011158 | P2: =AVERAGE(M2:O2) -> 0.39144584 | Q2: =0.4*H2+0.4*I2+0.2*P2 -> 0.38116777 | R2: =PERCENTILE($Q$2:$Q$800,0.75) -> 0.66771572 | S2: =OR(Q2>=R2,AND(B2="CW",COUNT(J2:L2)<3)) -> FALSE | T2: 0.23413931 | U2: 8.1936412 | V2: 0.38116777 | W2: =Q2-V2 -> 0
A3: 2021-01-04 | B3: CW | C3: 44.500267 | D3: =SUMPRODUCT(Risk_Inputs!B3:AJ3,Risk_Coefs!$B$2:$AJ$2) -> -0.9626899 | E3: =1/(1+EXP(-MAX(-25,MIN(25,D3)))) -> 0.27633996 | F3: =SUMPRODUCT(Risk_Inputs!B3:AJ3,Risk_Coefs!$B$3:$AJ$3) -> 10.931965 | G3: =MAX(0,F3) -> 10.931965 | H3: =(SUMPRODUCT(--ISNUMBER($E$2:$E$800),--($E$2:$E$800<E3))+(SUMPRODUCT(--ISNUMBER($E$2:$E$800),--($E$2:$E$800=E3))+1)/2)/COUNT($E$2:$E$800) -> 0.43679599 | I3: =(SUMPRODUCT(--ISNUMBER($G$2:$G$800),--($G$2:$G$800<G3))+(SUMPRODUCT(--ISNUMBER($G$2:$G$800),--($G$2:$G$800=G3))+1)/2)/COUNT($G$2:$G$800) -> 0.87484355 | J3: 39.395249 | K3: 3.6389083 | L3: 0.3265687 | M3: =IF(OR(B3="NW",COUNT(Risk_Rank_Keys!B3)=0),0.5,(SUMPRODUCT(--ISNUMBER(Risk_Rank_Keys!$B$2:$B$800),--(Risk_Rank_Keys!$B$2:$B$800<Risk_Rank_Keys!B3))+(SUMPRODUCT(--ISNUMBER(Risk_Rank_Keys!$B$2:$B$800),--(Risk_Rank_Keys!$B$2:$B$800=Risk_Rank_Keys!B3))+1)/2)/COUNT(Risk_Rank_Keys!$B$2:$B$800)) -> 0.9525802 | N3: =IF(OR(B3="NW",COUNT(Risk_Rank_Keys!C3)=0),0.5,(SUMPRODUCT(--ISNUMBER(Risk_Rank_Keys!$C$2:$C$800),--(Risk_Rank_Keys!$C$2:$C$800<Risk_Rank_Keys!C3))+(SUMPRODUCT(--ISNUMBER(Risk_Rank_Keys!$C$2:$C$800),--(Risk_Rank_Keys!$C$2:$C$800=Risk_Rank_Keys!C3))+1)/2)/COUNT(Risk_Rank_Keys!$C$2:$C$800)) -> 0.55230126 | O3: =IF(OR(B3="NW",COUNT(Risk_Rank_Keys!D3)=0),0.5,(SUMPRODUCT(--ISNUMBER(Risk_Rank_Keys!$D$2:$D$800),--(Risk_Rank_Keys!$D$2:$D$800<Risk_Rank_Keys!D3))+(SUMPRODUCT(--ISNUMBER(Risk_Rank_Keys!$D$2:$D$800),--(Risk_Rank_Keys!$D$2:$D$800=Risk_Rank_Keys!D3))+1)/2)/COUNT(Risk_Rank_Keys!$D$2:$D$800)) -> 0.79079498 | P3: =AVERAGE(M3:O3) -> 0.76522548 | Q3: =0.4*H3+0.4*I3+0.2*P3 -> 0.67770092 | R3: =PERCENTILE($Q$2:$Q$800,0.75) -> 0.66771572 | S3: =OR(Q3>=R3,AND(B3="CW",COUNT(J3:L3)<3)) -> TRUE | T3: 0.27633996 | U3: 10.931965 | V3: 0.67770092 | W3: =Q3-V3 -> 0
A4: 2021-01-05 | B4: CW | C4: -10.68427 | D4: =SUMPRODUCT(Risk_Inputs!B4:AJ4,Risk_Coefs!$B$2:$AJ$2) -> -1.433381 | E4: =1/(1+EXP(-MAX(-25,MIN(25,D4)))) -> 0.19257243 | F4: =SUMPRODUCT(Risk_Inputs!B4:AJ4,Risk_Coefs!$B$3:$AJ$3) -> 3.2210256 | G4: =MAX(0,F4) -> 3.2210256 | H4: =(SUMPRODUCT(--ISNUMBER($E$2:$E$800),--($E$2:$E$800<E4))+(SUMPRODUCT(--ISNUMBER($E$2:$E$800),--($E$2:$E$800=E4))+1)/2)/COUNT($E$2:$E$800) -> 0.09261577 | I4: =(SUMPRODUCT(--ISNUMBER($G$2:$G$800),--($G$2:$G$800<G4))+(SUMPRODUCT(--ISNUMBER($G$2:$G$800),--($G$2:$G$800=G4))+1)/2)/COUNT($G$2:$G$800) -> 0.030037547 | J4: 8.5577828 | K4: 3.7188873 | L4: 0.3806735 | M4: =IF(OR(B4="NW",COUNT(Risk_Rank_Keys!B4)=0),0.5,(SUMPRODUCT(--ISNUMBER(Risk_Rank_Keys!$B$2:$B$800),--(Risk_Rank_Keys!$B$2:$B$800<Risk_Rank_Keys!B4))+(SUMPRODUCT(--ISNUMBER(Risk_Rank_Keys!$B$2:$B$800),--(Risk_Rank_Keys!$B$2:$B$800=Risk_Rank_Keys!B4))+1)/2)/COUNT(Risk_Rank_Keys!$B$2:$B$800)) -> 0.42398884 | N4: =IF(OR(B4="NW",COUNT(Risk_Rank_Keys!C4)=0),0.5,(SUMPRODUCT(--ISNUMBER(Risk_Rank_Keys!$C$2:$C$800),--(Risk_Rank_Keys!$C$2:$C$800<Risk_Rank_Keys!C4))+(SUMPRODUCT(--ISNUMBER(Risk_Rank_Keys!$C$2:$C$800),--(Risk_Rank_Keys!$C$2:$C$800=Risk_Rank_Keys!C4))+1)/2)/COUNT(Risk_Rank_Keys!$C$2:$C$800)) -> 0.56206416 | O4: =IF(OR(B4="NW",COUNT(Risk_Rank_Keys!D4)=0),0.5,(SUMPRODUCT(--ISNUMBER(Risk_Rank_Keys!$D$2:$D$800),--(Risk_Rank_Keys!$D$2:$D$800<Risk_Rank_Keys!D4))+(SUMPRODUCT(--ISNUMBER(Risk_Rank_Keys!$D$2:$D$800),--(Risk_Rank_Keys!$D$2:$D$800=Risk_Rank_Keys!D4))+1)/2)/COUNT(Risk_Rank_Keys!$D$2:$D$800)) -> 0.86610879 | P4: =AVERAGE(M4:O4) -> 0.61738726 | Q4: =0.4*H4+0.4*I4+0.2*P4 -> 0.17253878 | R4: =PERCENTILE($Q$2:$Q$800,0.75) -> 0.66771572 | S4: =OR(Q4>=R4,AND(B4="CW",COUNT(J4:L4)<3)) -> FALSE | T4: 0.19257243 | U4: 3.2210256 | V4: 0.17253878 | W4: =Q4-V4 -> 0
A5: 2021-01-06 | B5: CW | C5: -45.306747 | D5: =SUMPRODUCT(Risk_Inputs!B5:AJ5,Risk_Coefs!$B$2:$AJ$2) -> -0.71682957 | E5: =1/(1+EXP(-MAX(-25,MIN(25,D5)))) -> 0.32809152 | F5: =SUMPRODUCT(Risk_Inputs!B5:AJ5,Risk_Coefs!$B$3:$AJ$3) -> 10.811768 | G5: =MAX(0,F5) -> 10.811768 | H5: =(SUMPRODUCT(--ISNUMBER($E$2:$E$800),--($E$2:$E$800<E5))+(SUMPRODUCT(--ISNUMBER($E$2:$E$800),--($E$2:$E$800=E5))+1)/2)/COUNT($E$2:$E$800) -> 0.72090113 | I5: =(SUMPRODUCT(--ISNUMBER($G$2:$G$800),--($G$2:$G$800<G5))+(SUMPRODUCT(--ISNUMBER($G$2:$G$800),--($G$2:$G$800=G5))+1)/2)/COUNT($G$2:$G$800) -> 0.86232791 | J5: 9.3975039 | K5: 1.6491228 | L5: 0.31578947 | M5: =IF(OR(B5="NW",COUNT(Risk_Rank_Keys!B5)=0),0.5,(SUMPRODUCT(--ISNUMBER(Risk_Rank_Keys!$B$2:$B$800),--(Risk_Rank_Keys!$B$2:$B$800<Risk_Rank_Keys!B5))+(SUMPRODUCT(--ISNUMBER(Risk_Rank_Keys!$B$2:$B$800),--(Risk_Rank_Keys!$B$2:$B$800=Risk_Rank_Keys!B5))+1)/2)/COUNT(Risk_Rank_Keys!$B$2:$B$800)) -> 0.46861925 | N5: =IF(OR(B5="NW",COUNT(Risk_Rank_Keys!C5)=0),0.5,(SUMPRODUCT(--ISNUMBER(Risk_Rank_Keys!$C$2:$C$800),--(Risk_Rank_Keys!$C$2:$C$800<Risk_Rank_Keys!C5))+(SUMPRODUCT(--ISNUMBER(Risk_Rank_Keys!$C$2:$C$800),--(Risk_Rank_Keys!$C$2:$C$800=Risk_Rank_Keys!C5))+1)/2)/COUNT(Risk_Rank_Keys!$C$2:$C$800)) -> 0.17433752 | O5: =IF(OR(B5="NW",COUNT(Risk_Rank_Keys!D5)=0),0.5,(SUMPRODUCT(--ISNUMBER(Risk_Rank_Keys!$D$2:$D$800),--(Risk_Rank_Keys!$D$2:$D$800<Risk_Rank_Keys!D5))+(SUMPRODUCT(--ISNUMBER(Risk_Rank_Keys!$D$2:$D$800),--(Risk_Rank_Keys!$D$2:$D$800=Risk_Rank_Keys!D5))+1)/2)/COUNT(Risk_Rank_Keys!$D$2:$D$800)) -> 0.76708508 | P5: =AVERAGE(M5:O5) -> 0.47001395 | Q5: =0.4*H5+0.4*I5+0.2*P5 -> 0.7272944 | R5: =PERCENTILE($Q$2:$Q$800,0.75) -> 0.66771572 | S5: =OR(Q5>=R5,AND(B5="CW",COUNT(J5:L5)<3)) -> TRUE | T5: 0.32809152 | U5: 10.811768 | V5: 0.7272944 | W5: =Q5-V5 -> 0
A6: 2021-01-07 | B6: CW | C6: 40.429445 | D6: =SUMPRODUCT(Risk_Inputs!B6:AJ6,Risk_Coefs!$B$2:$AJ$2) -> -0.81892913 | E6: =1/(1+EXP(-MAX(-25,MIN(25,D6)))) -> 0.30599102 | F6: =SUMPRODUCT(Risk_Inputs!B6:AJ6,Risk_Coefs!$B$3:$AJ$3) -> 8.8015052 | G6: =MAX(0,F6) -> 8.8015052 | H6: =(SUMPRODUCT(--ISNUMBER($E$2:$E$800),--($E$2:$E$800<E6))+(SUMPRODUCT(--ISNUMBER($E$2:$E$800),--($E$2:$E$800=E6))+1)/2)/COUNT($E$2:$E$800) -> 0.59824781 | I6: =(SUMPRODUCT(--ISNUMBER($G$2:$G$800),--($G$2:$G$800<G6))+(SUMPRODUCT(--ISNUMBER($G$2:$G$800),--($G$2:$G$800=G6))+1)/2)/COUNT($G$2:$G$800) -> 0.65206508 | J6: 5.8006272 | K6: 2.850062 | L6: 0.30978934 | M6: =IF(OR(B6="NW",COUNT(Risk_Rank_Keys!B6)=0),0.5,(SUMPRODUCT(--ISNUMBER(Risk_Rank_Keys!$B$2:$B$800),--(Risk_Rank_Keys!$B$2:$B$800<Risk_Rank_Keys!B6))+(SUMPRODUCT(--ISNUMBER(Risk_Rank_Keys!$B$2:$B$800),--(Risk_Rank_Keys!$B$2:$B$800=Risk_Rank_Keys!B6))+1)/2)/COUNT(Risk_Rank_Keys!$B$2:$B$800)) -> 0.20920502 | N6: =IF(OR(B6="NW",COUNT(Risk_Rank_Keys!C6)=0),0.5,(SUMPRODUCT(--ISNUMBER(Risk_Rank_Keys!$C$2:$C$800),--(Risk_Rank_Keys!$C$2:$C$800<Risk_Rank_Keys!C6))+(SUMPRODUCT(--ISNUMBER(Risk_Rank_Keys!$C$2:$C$800),--(Risk_Rank_Keys!$C$2:$C$800=Risk_Rank_Keys!C6))+1)/2)/COUNT(Risk_Rank_Keys!$C$2:$C$800)) -> 0.44909344 | O6: =IF(OR(B6="NW",COUNT(Risk_Rank_Keys!D6)=0),0.5,(SUMPRODUCT(--ISNUMBER(Risk_Rank_Keys!$D$2:$D$800),--(Risk_Rank_Keys!$D$2:$D$800<Risk_Rank_Keys!D6))+(SUMPRODUCT(--ISNUMBER(Risk_Rank_Keys!$D$2:$D$800),--(Risk_Rank_Keys!$D$2:$D$800=Risk_Rank_Keys!D6))+1)/2)/COUNT(Risk_Rank_Keys!$D$2:$D$800)) -> 0.75732218 | P6: =AVERAGE(M6:O6) -> 0.47187355 | Q6: =0.4*H6+0.4*I6+0.2*P6 -> 0.59449987 | R6: =PERCENTILE($Q$2:$Q$800,0.75) -> 0.66771572 | S6: =OR(Q6>=R6,AND(B6="CW",COUNT(J6:L6)<3)) -> FALSE | T6: 0.30599102 | U6: 8.8015052 | V6: 0.59449987 | W6: =Q6-V6 -> 0
A7: 2021-01-11 | B7: CW | C7: -37.921812 | D7: =SUMPRODUCT(Risk_Inputs!B7:AJ7,Risk_Coefs!$B$2:$AJ$2) -> -0.5881178 | E7: =1/(1+EXP(-MAX(-25,MIN(25,D7)))) -> 0.35706683 | F7: =SUMPRODUCT(Risk_Inputs!B7:AJ7,Risk_Coefs!$B$3:$AJ$3) -> 10.277981 | G7: =MAX(0,F7) -> 10.277981 | H7: =(SUMPRODUCT(--ISNUMBER($E$2:$E$800),--($E$2:$E$800<E7))+(SUMPRODUCT(--ISNUMBER($E$2:$E$800),--($E$2:$E$800=E7))+1)/2)/COUNT($E$2:$E$800) -> 0.83354193 | I7: =(SUMPRODUCT(--ISNUMBER($G$2:$G$800),--($G$2:$G$800<G7))+(SUMPRODUCT(--ISNUMBER($G$2:$G$800),--($G$2:$G$800=G7))+1)/2)/COUNT($G$2:$G$800) -> 0.81977472 | J7: 10.382918 | K7: 2.8862077 | L7: 0.26023184 | M7: =IF(OR(B7="NW",COUNT(Risk_Rank_Keys!B7)=0),0.5,(SUMPRODUCT(--ISNUMBER(Risk_Rank_Keys!$B$2:$B$800),--(Risk_Rank_Keys!$B$2:$B$800<Risk_Rank_Keys!B7))+(SUMPRODUCT(--ISNUMBER(Risk_Rank_Keys!$B$2:$B$800),--(Risk_Rank_Keys!$B$2:$B$800=Risk_Rank_Keys!B7))+1)/2)/COUNT(Risk_Rank_Keys!$B$2:$B$800)) -> 0.52580195 | N7: =IF(OR(B7="NW",COUNT(Risk_Rank_Keys!C7)=0),0.5,(SUMPRODUCT(--ISNUMBER(Risk_Rank_Keys!$C$2:$C$800),--(Risk_Rank_Keys!$C$2:$C$800<Risk_Rank_Keys!C7))+(SUMPRODUCT(--ISNUMBER(Risk_Rank_Keys!$C$2:$C$800),--(Risk_Rank_Keys!$C$2:$C$800=Risk_Rank_Keys!C7))+1)/2)/COUNT(Risk_Rank_Keys!$C$2:$C$800)) -> 0.45606695 | O7: =IF(OR(B7="NW",COUNT(Risk_Rank_Keys!D7)=0),0.5,(SUMPRODUCT(--ISNUMBER(Risk_Rank_Keys!$D$2:$D$800),--(Risk_Rank_Keys!$D$2:$D$800<Risk_Rank_Keys!D7))+(SUMPRODUCT(--ISNUMBER(Risk_Rank_Keys!$D$2:$D$800),--(Risk_Rank_Keys!$D$2:$D$800=Risk_Rank_Keys!D7))+1)/2)/COUNT(Risk_Rank_Keys!$D$2:$D$800)) -> 0.63458856 | P7: =AVERAGE(M7:O7) -> 0.53881915 | Q7: =0.4*H7+0.4*I7+0.2*P7 -> 0.76909049 | R7: =PERCENTILE($Q$2:$Q$800,0.75) -> 0.66771572 | S7: =OR(Q7>=R7,AND(B7="CW",COUNT(J7:L7)<3)) -> TRUE | T7: 0.35706683 | U7: 10.277981 | V7: 0.76909049 | W7: =Q7-V7 -> 0
A8: 2021-01-12 | B8: CW | C8: 18.445431 | D8: =SUMPRODUCT(Risk_Inputs!B8:AJ8,Risk_Coefs!$B$2:$AJ$2) -> -0.90353874 | E8: =1/(1+EXP(-MAX(-25,MIN(25,D8)))) -> 0.28832383 | F8: =SUMPRODUCT(Risk_Inputs!B8:AJ8,Risk_Coefs!$B$3:$AJ$3) -> 7.1082222 | G8: =MAX(0,F8) -> 7.1082222 | H8: =(SUMPRODUCT(--ISNUMBER($E$2:$E$800),--($E$2:$E$800<E8))+(SUMPRODUCT(--ISNUMBER($E$2:$E$800),--($E$2:$E$800=E8))+1)/2)/COUNT($E$2:$E$800) -> 0.51188986 | I8: =(SUMPRODUCT(--ISNUMBER($G$2:$G$800),--($G$2:$G$800<G8))+(SUMPRODUCT(--ISNUMBER($G$2:$G$800),--($G$2:$G$800=G8))+1)/2)/COUNT($G$2:$G$800) -> 0.42928661 | J8: 6.1259241 | K8: 1.7466111 | L8: 0.31282586 | M8: =IF(OR(B8="NW",COUNT(Risk_Rank_Keys!B8)=0),0.5,(SUMPRODUCT(--ISNUMBER(Risk_Rank_Keys!$B$2:$B$800),--(Risk_Rank_Keys!$B$2:$B$800<Risk_Rank_Keys!B8))+(SUMPRODUCT(--ISNUMBER(Risk_Rank_Keys!$B$2:$B$800),--(Risk_Rank_Keys!$B$2:$B$800=Risk_Rank_Keys!B8))+1)/2)/COUNT(Risk_Rank_Keys!$B$2:$B$800)) -> 0.23291492 | N8: =IF(OR(B8="NW",COUNT(Risk_Rank_Keys!C8)=0),0.5,(SUMPRODUCT(--ISNUMBER(Risk_Rank_Keys!$C$2:$C$800),--(Risk_Rank_Keys!$C$2:$C$800<Risk_Rank_Keys!C8))+(SUMPRODUCT(--ISNUMBER(Risk_Rank_Keys!$C$2:$C$800),--(Risk_Rank_Keys!$C$2:$C$800=Risk_Rank_Keys!C8))+1)/2)/COUNT(Risk_Rank_Keys!$C$2:$C$800)) -> 0.20083682 | O8: =IF(OR(B8="NW",COUNT(Risk_Rank_Keys!D8)=0),0.5,(SUMPRODUCT(--ISNUMBER(Risk_Rank_Keys!$D$2:$D$800),--(Risk_Rank_Keys!$D$2:$D$800<Risk_Rank_Keys!D8))+(SUMPRODUCT(--ISNUMBER(Risk_Rank_Keys!$D$2:$D$800),--(Risk_Rank_Keys!$D$2:$D$800=Risk_Rank_Keys!D8))+1)/2)/COUNT(Risk_Rank_Keys!$D$2:$D$800)) -> 0.75871688 | P8: =AVERAGE(M8:O8) -> 0.39748954 | Q8: =0.4*H8+0.4*I8+0.2*P8 -> 0.4559685 | R8: =PERCENTILE($Q$2:$Q$800,0.75) -> 0.66771572 | S8: =OR(Q8>=R8,AND(B8="CW",COUNT(J8:L8)<3)) -> FALSE | T8: 0.28832383 | U8: 7.1082222 | V8: 0.4559685 | W8: =Q8-V8 -> 0
A9: 2021-01-13 | B9: CW | C9: 21.297182 | D9: =SUMPRODUCT(Risk_Inputs!B9:AJ9,Risk_Coefs!$B$2:$AJ$2) -> -0.72010648 | E9: =1/(1+EXP(-MAX(-25,MIN(25,D9)))) -> 0.32736954 | F9: =SUMPRODUCT(Risk_Inputs!B9:AJ9,Risk_Coefs!$B$3:$AJ$3) -> 9.4583689 | G9: =MAX(0,F9) -> 9.4583689 | H9: =(SUMPRODUCT(--ISNUMBER($E$2:$E$800),--($E$2:$E$800<E9))+(SUMPRODUCT(--ISNUMBER($E$2:$E$800),--($E$2:$E$800=E9))+1)/2)/COUNT($E$2:$E$800) -> 0.71714643 | I9: =(SUMPRODUCT(--ISNUMBER($G$2:$G$800),--($G$2:$G$800<G9))+(SUMPRODUCT(--ISNUMBER($G$2:$G$800),--($G$2:$G$800=G9))+1)/2)/COUNT($G$2:$G$800) -> 0.72340426 | J9: 4.0768783 | K9: 2.7191413 | L9: 0.32200358 | M9: =IF(OR(B9="NW",COUNT(Risk_Rank_Keys!B9)=0),0.5,(SUMPRODUCT(--ISNUMBER(Risk_Rank_Keys!$B$2:$B$800),--(Risk_Rank_Keys!$B$2:$B$800<Risk_Rank_Keys!B9))+(SUMPRODUCT(--ISNUMBER(Risk_Rank_Keys!$B$2:$B$800),--(Risk_Rank_Keys!$B$2:$B$800=Risk_Rank_Keys!B9))+1)/2)/COUNT(Risk_Rank_Keys!$B$2:$B$800)) -> 0.075313808 | N9: =IF(OR(B9="NW",COUNT(Risk_Rank_Keys!C9)=0),0.5,(SUMPRODUCT(--ISNUMBER(Risk_Rank_Keys!$C$2:$C$800),--(Risk_Rank_Keys!$C$2:$C$800<Risk_Rank_Keys!C9))+(SUMPRODUCT(--ISNUMBER(Risk_Rank_Keys!$C$2:$C$800),--(Risk_Rank_Keys!$C$2:$C$800=Risk_Rank_Keys!C9))+1)/2)/COUNT(Risk_Rank_Keys!$C$2:$C$800)) -> 0.42677824 | O9: =IF(OR(B9="NW",COUNT(Risk_Rank_Keys!D9)=0),0.5,(SUMPRODUCT(--ISNUMBER(Risk_Rank_Keys!$D$2:$D$800),--(Risk_Rank_Keys!$D$2:$D$800<Risk_Rank_Keys!D9))+(SUMPRODUCT(--ISNUMBER(Risk_Rank_Keys!$D$2:$D$800),--(Risk_Rank_Keys!$D$2:$D$800=Risk_Rank_Keys!D9))+1)/2)/COUNT(Risk_Rank_Keys!$D$2:$D$800)) -> 0.78242678 | P9: =AVERAGE(M9:O9) -> 0.42817294 | Q9: =0.4*H9+0.4*I9+0.2*P9 -> 0.66185486 | R9: =PERCENTILE($Q$2:$Q$800,0.75) -> 0.66771572 | S9: =OR(Q9>=R9,AND(B9="CW",COUNT(J9:L9)<3)) -> FALSE | T9: 0.32736954 | U9: 9.4583689 | V9: 0.66185486 | W9: =Q9-V9 -> 0
A10: 2021-01-14 | B10: CW | C10: 25.737829 | D10: =SUMPRODUCT(Risk_Inputs!B10:AJ10,Risk_Coefs!$B$2:$AJ$2) -> -0.96906545 | E10: =1/(1+EXP(-MAX(-25,MIN(25,D10)))) -> 0.27506682 | F10: =SUMPRODUCT(Risk_Inputs!B10:AJ10,Risk_Coefs!$B$3:$AJ$3) -> 7.4153155 | G10: =MAX(0,F10) -> 7.4153155 | H10: =(SUMPRODUCT(--ISNUMBER($E$2:$E$800),--($E$2:$E$800<E10))+(SUMPRODUCT(--ISNUMBER($E$2:$E$800),--($E$2:$E$800=E10))+1)/2)/COUNT($E$2:$E$800) -> 0.42428035 | I10: =(SUMPRODUCT(--ISNUMBER($G$2:$G$800),--($G$2:$G$800<G10))+(SUMPRODUCT(--ISNUMBER($G$2:$G$800),--($G$2:$G$800=G10))+1)/2)/COUNT($G$2:$G$800) -> 0.46057572 | J10: 6.4240638 | K10: 3.3197437 | L10: 0.46592895 | M10: =IF(OR(B10="NW",COUNT(Risk_Rank_Keys!B10)=0),0.5,(SUMPRODUCT(--ISNUMBER(Risk_Rank_Keys!$B$2:$B$800),--(Risk_Rank_Keys!$B$2:$B$800<Risk_Rank_Keys!B10))+(SUMPRODUCT(--ISNUMBER(Risk_Rank_Keys!$B$2:$B$800),--(Risk_Rank_Keys!$B$2:$B$800=Risk_Rank_Keys!B10))+1)/2)/COUNT(Risk_Rank_Keys!$B$2:$B$800)) -> 0.26917713 | N10: =IF(OR(B10="NW",COUNT(Risk_Rank_Keys!C10)=0),0.5,(SUMPRODUCT(--ISNUMBER(Risk_Rank_Keys!$C$2:$C$800),--(Risk_Rank_Keys!$C$2:$C$800<Risk_Rank_Keys!C10))+(SUMPRODUCT(--ISNUMBER(Risk_Rank_Keys!$C$2:$C$800),--(Risk_Rank_Keys!$C$2:$C$800=Risk_Rank_Keys!C10))+1)/2)/COUNT(Risk_Rank_Keys!$C$2:$C$800)) -> 0.51046025 | O10: =IF(OR(B10="NW",COUNT(Risk_Rank_Keys!D10)=0),0.5,(SUMPRODUCT(--ISNUMBER(Risk_Rank_Keys!$D$2:$D$800),--(Risk_Rank_Keys!$D$2:$D$800<Risk_Rank_Keys!D10))+(SUMPRODUCT(--ISNUMBER(Risk_Rank_Keys!$D$2:$D$800),--(Risk_Rank_Keys!$D$2:$D$800=Risk_Rank_Keys!D10))+1)/2)/COUNT(Risk_Rank_Keys!$D$2:$D$800)) -> 0.93444909 | P10: =AVERAGE(M10:O10) -> 0.57136216 | Q10: =0.4*H10+0.4*I10+0.2*P10 -> 0.46821486 | R10: =PERCENTILE($Q$2:$Q$800,0.75) -> 0.66771572 | S10: =OR(Q10>=R10,AND(B10="CW",COUNT(J10:L10)<3)) -> FALSE | T10: 0.27506682 | U10: 7.4153155 | V10: 0.46821486 | W10: =Q10-V10 -> 0
A11: 2021-01-15 | B11: CW | C11: -45.133894 | D11: =SUMPRODUCT(Risk_Inputs!B11:AJ11,Risk_Coefs!$B$2:$AJ$2) -> -1.0623525 | E11: =1/(1+EXP(-MAX(-25,MIN(25,D11)))) -> 0.25686015 | F11: =SUMPRODUCT(Risk_Inputs!B11:AJ11,Risk_Coefs!$B$3:$AJ$3) -> 8.2013316 | G11: =MAX(0,F11) -> 8.2013316 | H11: =(SUMPRODUCT(--ISNUMBER($E$2:$E$800),--($E$2:$E$800<E11))+(SUMPRODUCT(--ISNUMBER($E$2:$E$800),--($E$2:$E$800=E11))+1)/2)/COUNT($E$2:$E$800) -> 0.30913642 | I11: =(SUMPRODUCT(--ISNUMBER($G$2:$G$800),--($G$2:$G$800<G11))+(SUMPRODUCT(--ISNUMBER($G$2:$G$800),--($G$2:$G$800=G11))+1)/2)/COUNT($G$2:$G$800) -> 0.56320401 | J11: 14.895067 | K11: 1.788067 | L11: 0.33879164 | M11: =IF(OR(B11="NW",COUNT(Risk_Rank_Keys!B11)=0),0.5,(SUMPRODUCT(--ISNUMBER(Risk_Rank_Keys!$B$2:$B$800),--(Risk_Rank_Keys!$B$2:$B$800<Risk_Rank_Keys!B11))+(SUMPRODUCT(--ISNUMBER(Risk_Rank_Keys!$B$2:$B$800),--(Risk_Rank_Keys!$B$2:$B$800=Risk_Rank_Keys!B11))+1)/2)/COUNT(Risk_Rank_Keys!$B$2:$B$800)) -> 0.70432357 | N11: =IF(OR(B11="NW",COUNT(Risk_Rank_Keys!C11)=0),0.5,(SUMPRODUCT(--ISNUMBER(Risk_Rank_Keys!$C$2:$C$800),--(Risk_Rank_Keys!$C$2:$C$800<Risk_Rank_Keys!C11))+(SUMPRODUCT(--ISNUMBER(Risk_Rank_Keys!$C$2:$C$800),--(Risk_Rank_Keys!$C$2:$C$800=Risk_Rank_Keys!C11))+1)/2)/COUNT(Risk_Rank_Keys!$C$2:$C$800)) -> 0.21059972 | O11: =IF(OR(B11="NW",COUNT(Risk_Rank_Keys!D11)=0),0.5,(SUMPRODUCT(--ISNUMBER(Risk_Rank_Keys!$D$2:$D$800),--(Risk_Rank_Keys!$D$2:$D$800<Risk_Rank_Keys!D11))+(SUMPRODUCT(--ISNUMBER(Risk_Rank_Keys!$D$2:$D$800),--(Risk_Rank_Keys!$D$2:$D$800=Risk_Rank_Keys!D11))+1)/2)/COUNT(Risk_Rank_Keys!$D$2:$D$800)) -> 0.81311018 | P11: =AVERAGE(M11:O11) -> 0.57601116 | Q11: =0.4*H11+0.4*I11+0.2*P11 -> 0.4641384 | R11: =PERCENTILE($Q$2:$Q$800,0.75) -> 0.66771572 | S11: =OR(Q11>=R11,AND(B11="CW",COUNT(J11:L11)<3)) -> FALSE | T11: 0.25686015 | U11: 8.2013316 | V11: 0.4641384 | W11: =Q11-V11 -> 0
A12: 2021-01-18 | B12: CW | C12: 11.478606 | D12: =SUMPRODUCT(Risk_Inputs!B12:AJ12,Risk_Coefs!$B$2:$AJ$2) -> -0.36923127 | E12: =1/(1+EXP(-MAX(-25,MIN(25,D12)))) -> 0.40872679 | F12: =SUMPRODUCT(Risk_Inputs!B12:AJ12,Risk_Coefs!$B$3:$AJ$3) -> 10.271132 | G12: =MAX(0,F12) -> 10.271132 | H12: =(SUMPRODUCT(--ISNUMBER($E$2:$E$800),--($E$2:$E$800<E12))+(SUMPRODUCT(--ISNUMBER($E$2:$E$800),--($E$2:$E$800=E12))+1)/2)/COUNT($E$2:$E$800) -> 0.95494368 | I12: =(SUMPRODUCT(--ISNUMBER($G$2:$G$800),--($G$2:$G$800<G12))+(SUMPRODUCT(--ISNUMBER($G$2:$G$800),--($G$2:$G$800=G12))+1)/2)/COUNT($G$2:$G$800) -> 0.81852315 | J12: 5.1077314 | K12: 1.1741683 | L12: 0.249066 | M12: =IF(OR(B12="NW",COUNT(Risk_Rank_Keys!B12)=0),0.5,(SUMPRODUCT(--ISNUMBER(Risk_Rank_Keys!$B$2:$B$800),--(Risk_Rank_Keys!$B$2:$B$800<Risk_Rank_Keys!B12))+(SUMPRODUCT(--ISNUMBER(Risk_Rank_Keys!$B$2:$B$800),--(Risk_Rank_Keys!$B$2:$B$800=Risk_Rank_Keys!B12))+1)/2)/COUNT(Risk_Rank_Keys!$B$2:$B$800)) -> 0.13947001 | N12: =IF(OR(B12="NW",COUNT(Risk_Rank_Keys!C12)=0),0.5,(SUMPRODUCT(--ISNUMBER(Risk_Rank_Keys!$C$2:$C$800),--(Risk_Rank_Keys!$C$2:$C$800<Risk_Rank_Keys!C12))+(SUMPRODUCT(--ISNUMBER(Risk_Rank_Keys!$C$2:$C$800),--(Risk_Rank_Keys!$C$2:$C$800=Risk_Rank_Keys!C12))+1)/2)/COUNT(Risk_Rank_Keys!$C$2:$C$800)) -> 0.062761506 | O12: =IF(OR(B12="NW",COUNT(Risk_Rank_Keys!D12)=0),0.5,(SUMPRODUCT(--ISNUMBER(Risk_Rank_Keys!$D$2:$D$800),--(Risk_Rank_Keys!$D$2:$D$800<Risk_Rank_Keys!D12))+(SUMPRODUCT(--ISNUMBER(Risk_Rank_Keys!$D$2:$D$800),--(Risk_Rank_Keys!$D$2:$D$800=Risk_Rank_Keys!D12))+1)/2)/COUNT(Risk_Rank_Keys!$D$2:$D$800)) -> 0.58158996 | P12: =AVERAGE(M12:O12) -> 0.26127383 | Q12: =0.4*H12+0.4*I12+0.2*P12 -> 0.7616415 | R12: =PERCENTILE($Q$2:$Q$800,0.75) -> 0.66771572 | S12: =OR(Q12>=R12,AND(B12="CW",COUNT(J12:L12)<3)) -> TRUE | T12: 0.40872679 | U12: 10.271132 | V12: 0.7616415 | W12: =Q12-V12 -> 0
A13: 2021-01-19 | B13: CW | C13: 39.151501 | D13: =SUMPRODUCT(Risk_Inputs!B13:AJ13,Risk_Coefs!$B$2:$AJ$2) -> -1.2949907 | E13: =1/(1+EXP(-MAX(-25,MIN(25,D13)))) -> 0.21500928 | F13: =SUMPRODUCT(Risk_Inputs!B13:AJ13,Risk_Coefs!$B$3:$AJ$3) -> 5.1535199 | G13: =MAX(0,F13) -> 5.1535199 | H13: =(SUMPRODUCT(--ISNUMBER($E$2:$E$800),--($E$2:$E$800<E13))+(SUMPRODUCT(--ISNUMBER($E$2:$E$800),--($E$2:$E$800=E13))+1)/2)/COUNT($E$2:$E$800) -> 0.1301627 | I13: =(SUMPRODUCT(--ISNUMBER($G$2:$G$800),--($G$2:$G$800<G13))+(SUMPRODUCT(--ISNUMBER($G$2:$G$800),--($G$2:$G$800=G13))+1)/2)/COUNT($G$2:$G$800) -> 0.15769712 | J13: 10.614307 | K13: 5.2358491 | L13: 0.56603774 | M13: =IF(OR(B13="NW",COUNT(Risk_Rank_Keys!B13)=0),0.5,(SUMPRODUCT(--ISNUMBER(Risk_Rank_Keys!$B$2:$B$800),--(Risk_Rank_Keys!$B$2:$B$800<Risk_Rank_Keys!B13))+(SUMPRODUCT(--ISNUMBER(Risk_Rank_Keys!$B$2:$B$800),--(Risk_Rank_Keys!$B$2:$B$800=Risk_Rank_Keys!B13))+1)/2)/COUNT(Risk_Rank_Keys!$B$2:$B$800)) -> 0.53417015 | N13: =IF(OR(B13="NW",COUNT(Risk_Rank_Keys!C13)=0),0.5,(SUMPRODUCT(--ISNUMBER(Risk_Rank_Keys!$C$2:$C$800),--(Risk_Rank_Keys!$C$2:$C$800<Risk_Rank_Keys!C13))+(SUMPRODUCT(--ISNUMBER(Risk_Rank_Keys!$C$2:$C$800),--(Risk_Rank_Keys!$C$2:$C$800=Risk_Rank_Keys!C13))+1)/2)/COUNT(Risk_Rank_Keys!$C$2:$C$800)) -> 0.70432357 | O13: =IF(OR(B13="NW",COUNT(Risk_Rank_Keys!D13)=0),0.5,(SUMPRODUCT(--ISNUMBER(Risk_Rank_Keys!$D$2:$D$800),--(Risk_Rank_Keys!$D$2:$D$800<Risk_Rank_Keys!D13))+(SUMPRODUCT(--ISNUMBER(Risk_Rank_Keys!$D$2:$D$800),--(Risk_Rank_Keys!$D$2:$D$800=Risk_Rank_Keys!D13))+1)/2)/COUNT(Risk_Rank_Keys!$D$2:$D$800)) -> 0.9679219 | P13: =AVERAGE(M13:O13) -> 0.73547187 | Q13: =0.4*H13+0.4*I13+0.2*P13 -> 0.2622383 | R13: =PERCENTILE($Q$2:$Q$800,0.75) -> 0.66771572 | S13: =OR(Q13>=R13,AND(B13="CW",COUNT(J13:L13)<3)) -> FALSE | T13: 0.21500928 | U13: 5.1535199 | V13: 0.2622383 | W13: =Q13-V13 -> 0
A14: 2021-01-20 | B14: CW | C14: 55.067721 | D14: =SUMPRODUCT(Risk_Inputs!B14:AJ14,Risk_Coefs!$B$2:$AJ$2) -> -1.1016783 | E14: =1/(1+EXP(-MAX(-25,MIN(25,D14)))) -> 0.24942557 | F14: =SUMPRODUCT(Risk_Inputs!B14:AJ14,Risk_Coefs!$B$3:$AJ$3) -> 6.6720597 | G14: =MAX(0,F14) -> 6.6720597 | H14: =(SUMPRODUCT(--ISNUMBER($E$2:$E$800),--($E$2:$E$800<E14))+(SUMPRODUCT(--ISNUMBER($E$2:$E$800),--($E$2:$E$800=E14))+1)/2)/COUNT($E$2:$E$800) -> 0.26157697 | I14: =(SUMPRODUCT(--ISNUMBER($G$2:$G$800),--($G$2:$G$800<G14))+(SUMPRODUCT(--ISNUMBER($G$2:$G$800),--($G$2:$G$800=G14))+1)/2)/COUNT($G$2:$G$800) -> 0.37546934 | J14: 8.4278746 | K14: 7.4086604 | L14: 0.47361299 | M14: =IF(OR(B14="NW",COUNT(Risk_Rank_Keys!B14)=0),0.5,(SUMPRODUCT(--ISNUMBER(Risk_Rank_Keys!$B$2:$B$800),--(Risk_Rank_Keys!$B$2:$B$800<Risk_Rank_Keys!B14))+(SUMPRODUCT(--ISNUMBER(Risk_Rank_Keys!$B$2:$B$800),--(Risk_Rank_Keys!$B$2:$B$800=Risk_Rank_Keys!B14))+1)/2)/COUNT(Risk_Rank_Keys!$B$2:$B$800)) -> 0.41143654 | N14: =IF(OR(B14="NW",COUNT(Risk_Rank_Keys!C14)=0),0.5,(SUMPRODUCT(--ISNUMBER(Risk_Rank_Keys!$C$2:$C$800),--(Risk_Rank_Keys!$C$2:$C$800<Risk_Rank_Keys!C14))+(SUMPRODUCT(--ISNUMBER(Risk_Rank_Keys!$C$2:$C$800),--(Risk_Rank_Keys!$C$2:$C$800=Risk_Rank_Keys!C14))+1)/2)/COUNT(Risk_Rank_Keys!$C$2:$C$800)) -> 0.80195258 | O14: =IF(OR(B14="NW",COUNT(Risk_Rank_Keys!D14)=0),0.5,(SUMPRODUCT(--ISNUMBER(Risk_Rank_Keys!$D$2:$D$800),--(Risk_Rank_Keys!$D$2:$D$800<Risk_Rank_Keys!D14))+(SUMPRODUCT(--ISNUMBER(Risk_Rank_Keys!$D$2:$D$800),--(Risk_Rank_Keys!$D$2:$D$800=Risk_Rank_Keys!D14))+1)/2)/COUNT(Risk_Rank_Keys!$D$2:$D$800)) -> 0.94142259 | P14: =AVERAGE(M14:O14) -> 0.71827057 | Q14: =0.4*H14+0.4*I14+0.2*P14 -> 0.39847264 | R14: =PERCENTILE($Q$2:$Q$800,0.75) -> 0.66771572 | S14: =OR(Q14>=R14,AND(B14="CW",COUNT(J14:L14)<3)) -> FALSE | T14: 0.24942557 | U14: 6.6720597 | V14: 0.39847264 | W14: =Q14-V14 -> 0
A15: 2021-01-21 | B15: CW | C15: 36.437411 | D15: =SUMPRODUCT(Risk_Inputs!B15:AJ15,Risk_Coefs!$B$2:$AJ$2) -> -0.33964602 | E15: =1/(1+EXP(-MAX(-25,MIN(25,D15)))) -> 0.41589546 | F15: =SUMPRODUCT(Risk_Inputs!B15:AJ15,Risk_Coefs!$B$3:$AJ$3) -> 13.543477 | G15: =MAX(0,F15) -> 13.543477 | H15: =(SUMPRODUCT(--ISNUMBER($E$2:$E$800),--($E$2:$E$800<E15))+(SUMPRODUCT(--ISNUMBER($E$2:$E$800),--($E$2:$E$800=E15))+1)/2)/COUNT($E$2:$E$800) -> 0.96245307 | I15: =(SUMPRODUCT(--ISNUMBER($G$2:$G$800),--($G$2:$G$800<G15))+(SUMPRODUCT(--ISNUMBER($G$2:$G$800),--($G$2:$G$800=G15))+1)/2)/COUNT($G$2:$G$800) -> 0.96370463 | M15: =IF(OR(B15="NW",COUNT(Risk_Rank_Keys!B15)=0),0.5,(SUMPRODUCT(--ISNUMBER(Risk_Rank_Keys!$B$2:$B$800),--(Risk_Rank_Keys!$B$2:$B$800<Risk_Rank_Keys!B15))+(SUMPRODUCT(--ISNUMBER(Risk_Rank_Keys!$B$2:$B$800),--(Risk_Rank_Keys!$B$2:$B$800=Risk_Rank_Keys!B15))+1)/2)/COUNT(Risk_Rank_Keys!$B$2:$B$800)) -> 0.5 | N15: =IF(OR(B15="NW",COUNT(Risk_Rank_Keys!C15)=0),0.5,(SUMPRODUCT(--ISNUMBER(Risk_Rank_Keys!$C$2:$C$800),--(Risk_Rank_Keys!$C$2:$C$800<Risk_Rank_Keys!C15))+(SUMPRODUCT(--ISNUMBER(Risk_Rank_Keys!$C$2:$C$800),--(Risk_Rank_Keys!$C$2:$C$800=Risk_Rank_Keys!C15))+1)/2)/COUNT(Risk_Rank_Keys!$C$2:$C$800)) -> 0.5 | O15: =IF(OR(B15="NW",COUNT(Risk_Rank_Keys!D15)=0),0.5,(SUMPRODUCT(--ISNUMBER(Risk_Rank_Keys!$D$2:$D$800),--(Risk_Rank_Keys!$D$2:$D$800<Risk_Rank_Keys!D15))+(SUMPRODUCT(--ISNUMBER(Risk_Rank_Keys!$D$2:$D$800),--(Risk_Rank_Keys!$D$2:$D$800=Risk_Rank_Keys!D15))+1)/2)/COUNT(Risk_Rank_Keys!$D$2:$D$800)) -> 0.5 | P15: =AVERAGE(M15:O15) -> 0.5 | Q15: =0.4*H15+0.4*I15+0.2*P15 -> 0.87046308 | R15: =PERCENTILE($Q$2:$Q$800,0.75) -> 0.66771572 | S15: =OR(Q15>=R15,AND(B15="CW",COUNT(J15:L15)<3)) -> TRUE | T15: 0.41589546 | U15: 13.543477 | V15: 0.87046308 | W15: =Q15-V15 -> 0
A16: 2021-01-22 | B16: CW | C16: -40.91495 | D16: =SUMPRODUCT(Risk_Inputs!B16:AJ16,Risk_Coefs!$B$2:$AJ$2) -> -0.53908671 | E16: =1/(1+EXP(-MAX(-25,MIN(25,D16)))) -> 0.36840006 | F16: =SUMPRODUCT(Risk_Inputs!B16:AJ16,Risk_Coefs!$B$3:$AJ$3) -> 13.782778 | G16: =MAX(0,F16) -> 13.782778 | H16: =(SUMPRODUCT(--ISNUMBER($E$2:$E$800),--($E$2:$E$800<E16))+(SUMPRODUCT(--ISNUMBER($E$2:$E$800),--($E$2:$E$800=E16))+1)/2)/COUNT($E$2:$E$800) -> 0.8660826 | I16: =(SUMPRODUCT(--ISNUMBER($G$2:$G$800),--($G$2:$G$800<G16))+(SUMPRODUCT(--ISNUMBER($G$2:$G$800),--($G$2:$G$800=G16))+1)/2)/COUNT($G$2:$G$800) -> 0.96620776 | J16: 7.4583318 | K16: 1.6354746 | L16: 0.28662957 | M16: =IF(OR(B16="NW",COUNT(Risk_Rank_Keys!B16)=0),0.5,(SUMPRODUCT(--ISNUMBER(Risk_Rank_Keys!$B$2:$B$800),--(Risk_Rank_Keys!$B$2:$B$800<Risk_Rank_Keys!B16))+(SUMPRODUCT(--ISNUMBER(Risk_Rank_Keys!$B$2:$B$800),--(Risk_Rank_Keys!$B$2:$B$800=Risk_Rank_Keys!B16))+1)/2)/COUNT(Risk_Rank_Keys!$B$2:$B$800)) -> 0.35285914 | N16: =IF(OR(B16="NW",COUNT(Risk_Rank_Keys!C16)=0),0.5,(SUMPRODUCT(--ISNUMBER(Risk_Rank_Keys!$C$2:$C$800),--(Risk_Rank_Keys!$C$2:$C$800<Risk_Rank_Keys!C16))+(SUMPRODUCT(--ISNUMBER(Risk_Rank_Keys!$C$2:$C$800),--(Risk_Rank_Keys!$C$2:$C$800=Risk_Rank_Keys!C16))+1)/2)/COUNT(Risk_Rank_Keys!$C$2:$C$800)) -> 0.17154812 | O16: =IF(OR(B16="NW",COUNT(Risk_Rank_Keys!D16)=0),0.5,(SUMPRODUCT(--ISNUMBER(Risk_Rank_Keys!$D$2:$D$800),--(Risk_Rank_Keys!$D$2:$D$800<Risk_Rank_Keys!D16))+(SUMPRODUCT(--ISNUMBER(Risk_Rank_Keys!$D$2:$D$800),--(Risk_Rank_Keys!$D$2:$D$800=Risk_Rank_Keys!D16))+1)/2)/COUNT(Risk_Rank_Keys!$D$2:$D$800)) -> 0.71687587 | P16: =AVERAGE(M16:O16) -> 0.41376104 | Q16: =0.4*H16+0.4*I16+0.2*P16 -> 0.81566835 | R16: =PERCENTILE($Q$2:$Q$800,0.75) -> 0.66771572 | S16: =OR(Q16>=R16,AND(B16="CW",COUNT(J16:L16)<3)) -> TRUE | T16: 0.36840006 | U16: 13.782778 | V16: 0.81566835 | W16: =Q16-V16 -> 0
A17: 2021-01-25 | B17: CW | C17: -38.683927 | D17: =SUMPRODUCT(Risk_Inputs!B17:AJ17,Risk_Coefs!$B$2:$AJ$2) -> -0.6189083 | E17: =1/(1+EXP(-MAX(-25,MIN(25,D17)))) -> 0.35002978 | F17: =SUMPRODUCT(Risk_Inputs!B17:AJ17,Risk_Coefs!$B$3:$AJ$3) -> 12.185686 | G17: =MAX(0,F17) -> 12.185686 | H17: =(SUMPRODUCT(--ISNUMBER($E$2:$E$800),--($E$2:$E$800<E17))+(SUMPRODUCT(--ISNUMBER($E$2:$E$800),--($E$2:$E$800=E17))+1)/2)/COUNT($E$2:$E$800) -> 0.81602003 | I17: =(SUMPRODUCT(--ISNUMBER($G$2:$G$800),--($G$2:$G$800<G17))+(SUMPRODUCT(--ISNUMBER($G$2:$G$800),--($G$2:$G$800=G17))+1)/2)/COUNT($G$2:$G$800) -> 0.92866083 | J17: 16.72885 | K17: 2.2686208 | L17: 0.32122064 | M17: =IF(OR(B17="NW",COUNT(Risk_Rank_Keys!B17)=0),0.5,(SUMPRODUCT(--ISNUMBER(Risk_Rank_Keys!$B$2:$B$800),--(Risk_Rank_Keys!$B$2:$B$800<Risk_Rank_Keys!B17))+(SUMPRODUCT(--ISNUMBER(Risk_Rank_Keys!$B$2:$B$800),--(Risk_Rank_Keys!$B$2:$B$800=Risk_Rank_Keys!B17))+1)/2)/COUNT(Risk_Rank_Keys!$B$2:$B$800)) -> 0.74058577 | N17: =IF(OR(B17="NW",COUNT(Risk_Rank_Keys!C17)=0),0.5,(SUMPRODUCT(--ISNUMBER(Risk_Rank_Keys!$C$2:$C$800),--(Risk_Rank_Keys!$C$2:$C$800<Risk_Rank_Keys!C17))+(SUMPRODUCT(--ISNUMBER(Risk_Rank_Keys!$C$2:$C$800),--(Risk_Rank_Keys!$C$2:$C$800=Risk_Rank_Keys!C17))+1)/2)/COUNT(Risk_Rank_Keys!$C$2:$C$800)) -> 0.32775453 | O17: =IF(OR(B17="NW",COUNT(Risk_Rank_Keys!D17)=0),0.5,(SUMPRODUCT(--ISNUMBER(Risk_Rank_Keys!$D$2:$D$800),--(Risk_Rank_Keys!$D$2:$D$800<Risk_Rank_Keys!D17))+(SUMPRODUCT(--ISNUMBER(Risk_Rank_Keys!$D$2:$D$800),--(Risk_Rank_Keys!$D$2:$D$800=Risk_Rank_Keys!D17))+1)/2)/COUNT(Risk_Rank_Keys!$D$2:$D$800)) -> 0.77824268 | P17: =AVERAGE(M17:O17) -> 0.61552766 | Q17: =0.4*H17+0.4*I17+0.2*P17 -> 0.82097787 | R17: =PERCENTILE($Q$2:$Q$800,0.75) -> 0.66771572 | S17: =OR(Q17>=R17,AND(B17="CW",COUNT(J17:L17)<3)) -> TRUE | T17: 0.35002978 | U17: 12.185686 | V17: 0.82097787 | W17: =Q17-V17 -> 0
A18: 2021-01-27 | B18: CW | C18: 48.260157 | D18: =SUMPRODUCT(Risk_Inputs!B18:AJ18,Risk_Coefs!$B$2:$AJ$2) -> -1.4721172 | E18: =1/(1+EXP(-MAX(-25,MIN(25,D18)))) -> 0.18662102 | F18: =SUMPRODUCT(Risk_Inputs!B18:AJ18,Risk_Coefs!$B$3:$AJ$3) -> 5.8428267 | G18: =MAX(0,F18) -> 5.8428267 | H18: =(SUMPRODUCT(--ISNUMBER($E$2:$E$800),--($E$2:$E$800<E18))+(SUMPRODUCT(--ISNUMBER($E$2:$E$800),--($E$2:$E$800=E18))+1)/2)/COUNT($E$2:$E$800) -> 0.075093867 | I18: =(SUMPRODUCT(--ISNUMBER($G$2:$G$800),--($G$2:$G$800<G18))+(SUMPRODUCT(--ISNUMBER($G$2:$G$800),--($G$2:$G$800=G18))+1)/2)/COUNT($G$2:$G$800) -> 0.24530663 | J18: 37.435212 | K18: 9.6825397 | L18: 1.3756614 | M18: =IF(OR(B18="NW",COUNT(Risk_Rank_Keys!B18)=0),0.5,(SUMPRODUCT(--ISNUMBER(Risk_Rank_Keys!$B$2:$B$800),--(Risk_Rank_Keys!$B$2:$B$800<Risk_Rank_Keys!B18))+(SUMPRODUCT(--ISNUMBER(Risk_Rank_Keys!$B$2:$B$800),--(Risk_Rank_Keys!$B$2:$B$800=Risk_Rank_Keys!B18))+1)/2)/COUNT(Risk_Rank_Keys!$B$2:$B$800)) -> 0.94142259 | N18: =IF(OR(B18="NW",COUNT(Risk_Rank_Keys!C18)=0),0.5,(SUMPRODUCT(--ISNUMBER(Risk_Rank_Keys!$C$2:$C$800),--(Risk_Rank_Keys!$C$2:$C$800<Risk_Rank_Keys!C18))+(SUMPRODUCT(--ISNUMBER(Risk_Rank_Keys!$C$2:$C$800),--(Risk_Rank_Keys!$C$2:$C$800=Risk_Rank_Keys!C18))+1)/2)/COUNT(Risk_Rank_Keys!$C$2:$C$800)) -> 0.87447699 | O18: =IF(OR(B18="NW",COUNT(Risk_Rank_Keys!D18)=0),0.5,(SUMPRODUCT(--ISNUMBER(Risk_Rank_Keys!$D$2:$D$800),--(Risk_Rank_Keys!$D$2:$D$800<Risk_Rank_Keys!D18))+(SUMPRODUCT(--ISNUMBER(Risk_Rank_Keys!$D$2:$D$800),--(Risk_Rank_Keys!$D$2:$D$800=Risk_Rank_Keys!D18))+1)/2)/COUNT(Risk_Rank_Keys!$D$2:$D$800)) -> 1 | P18: =AVERAGE(M18:O18) -> 0.93863319 | Q18: =0.4*H18+0.4*I18+0.2*P18 -> 0.31588684 | R18: =PERCENTILE($Q$2:$Q$800,0.75) -> 0.66771572 | S18: =OR(Q18>=R18,AND(B18="CW",COUNT(J18:L18)<3)) -> FALSE | T18: 0.18662102 | U18: 5.8428267 | V18: 0.31588684 | W18: =Q18-V18 -> 0
A19: 2021-01-28 | B19: CW | C19: -12.881305 | D19: =SUMPRODUCT(Risk_Inputs!B19:AJ19,Risk_Coefs!$B$2:$AJ$2) -> -1.092653 | E19: =1/(1+EXP(-MAX(-25,MIN(25,D19)))) -> 0.25111903 | F19: =SUMPRODUCT(Risk_Inputs!B19:AJ19,Risk_Coefs!$B$3:$AJ$3) -> 7.1241508 | G19: =MAX(0,F19) -> 7.1241508 | H19: =(SUMPRODUCT(--ISNUMBER($E$2:$E$800),--($E$2:$E$800<E19))+(SUMPRODUCT(--ISNUMBER($E$2:$E$800),--($E$2:$E$800=E19))+1)/2)/COUNT($E$2:$E$800) -> 0.27158949 | I19: =(SUMPRODUCT(--ISNUMBER($G$2:$G$800),--($G$2:$G$800<G19))+(SUMPRODUCT(--ISNUMBER($G$2:$G$800),--($G$2:$G$800=G19))+1)/2)/COUNT($G$2:$G$800) -> 0.43178974 | J19: 24.5601 | K19: 4.7879617 | L19: 0.45599635 | M19: =IF(OR(B19="NW",COUNT(Risk_Rank_Keys!B19)=0),0.5,(SUMPRODUCT(--ISNUMBER(Risk_Rank_Keys!$B$2:$B$800),--(Risk_Rank_Keys!$B$2:$B$800<Risk_Rank_Keys!B19))+(SUMPRODUCT(--ISNUMBER(Risk_Rank_Keys!$B$2:$B$800),--(Risk_Rank_Keys!$B$2:$B$800=Risk_Rank_Keys!B19))+1)/2)/COUNT(Risk_Rank_Keys!$B$2:$B$800)) -> 0.85076709 | N19: =IF(OR(B19="NW",COUNT(Risk_Rank_Keys!C19)=0),0.5,(SUMPRODUCT(--ISNUMBER(Risk_Rank_Keys!$C$2:$C$800),--(Risk_Rank_Keys!$C$2:$C$800<Risk_Rank_Keys!C19))+(SUMPRODUCT(--ISNUMBER(Risk_Rank_Keys!$C$2:$C$800),--(Risk_Rank_Keys!$C$2:$C$800=Risk_Rank_Keys!C19))+1)/2)/COUNT(Risk_Rank_Keys!$C$2:$C$800)) -> 0.67085077 | O19: =IF(OR(B19="NW",COUNT(Risk_Rank_Keys!D19)=0),0.5,(SUMPRODUCT(--ISNUMBER(Risk_Rank_Keys!$D$2:$D$800),--(Risk_Rank_Keys!$D$2:$D$800<Risk_Rank_Keys!D19))+(SUMPRODUCT(--ISNUMBER(Risk_Rank_Keys!$D$2:$D$800),--(Risk_Rank_Keys!$D$2:$D$800=Risk_Rank_Keys!D19))+1)/2)/COUNT(Risk_Rank_Keys!$D$2:$D$800)) -> 0.93026499 | P19: =AVERAGE(M19:O19) -> 0.81729428 | Q19: =0.4*H19+0.4*I19+0.2*P19 -> 0.44481055 | R19: =PERCENTILE($Q$2:$Q$800,0.75) -> 0.66771572 | S19: =OR(Q19>=R19,AND(B19="CW",COUNT(J19:L19)<3)) -> FALSE | T19: 0.25111903 | U19: 7.1241508 | V19: 0.44481055 | W19: =Q19-V19 -> 0
A20: 2021-01-29 | B20: CW | C20: -42.994228 | D20: =SUMPRODUCT(Risk_Inputs!B20:AJ20,Risk_Coefs!$B$2:$AJ$2) -> -1.5354063 | E20: =1/(1+EXP(-MAX(-25,MIN(25,D20)))) -> 0.17720405 | F20: =SUMPRODUCT(Risk_Inputs!B20:AJ20,Risk_Coefs!$B$3:$AJ$3) -> 9.7457964 | G20: =MAX(0,F20) -> 9.7457964 | H20: =(SUMPRODUCT(--ISNUMBER($E$2:$E$800),--($E$2:$E$800<E20))+(SUMPRODUCT(--ISNUMBER($E$2:$E$800),--($E$2:$E$800=E20))+1)/2)/COUNT($E$2:$E$800) -> 0.058823529 | I20: =(SUMPRODUCT(--ISNUMBER($G$2:$G$800),--($G$2:$G$800<G20))+(SUMPRODUCT(--ISNUMBER($G$2:$G$800),--($G$2:$G$800=G20))+1)/2)/COUNT($G$2:$G$800) -> 0.7571965 | J20: 59.808183 | K20: 8.0519182 | L20: 0.32161728 | M20: =IF(OR(B20="NW",COUNT(Risk_Rank_Keys!B20)=0),0.5,(SUMPRODUCT(--ISNUMBER(Risk_Rank_Keys!$B$2:$B$800),--(Risk_Rank_Keys!$B$2:$B$800<Risk_Rank_Keys!B20))+(SUMPRODUCT(--ISNUMBER(Risk_Rank_Keys!$B$2:$B$800),--(Risk_Rank_Keys!$B$2:$B$800=Risk_Rank_Keys!B20))+1)/2)/COUNT(Risk_Rank_Keys!$B$2:$B$800)) -> 0.9902371 | N20: =IF(OR(B20="NW",COUNT(Risk_Rank_Keys!C20)=0),0.5,(SUMPRODUCT(--ISNUMBER(Risk_Rank_Keys!$C$2:$C$800),--(Risk_Rank_Keys!$C$2:$C$800<Risk_Rank_Keys!C20))+(SUMPRODUCT(--ISNUMBER(Risk_Rank_Keys!$C$2:$C$800),--(Risk_Rank_Keys!$C$2:$C$800=Risk_Rank_Keys!C20))+1)/2)/COUNT(Risk_Rank_Keys!$C$2:$C$800)) -> 0.82287308 | O20: =IF(OR(B20="NW",COUNT(Risk_Rank_Keys!D20)=0),0.5,(SUMPRODUCT(--ISNUMBER(Risk_Rank_Keys!$D$2:$D$800),--(Risk_Rank_Keys!$D$2:$D$800<Risk_Rank_Keys!D20))+(SUMPRODUCT(--ISNUMBER(Risk_Rank_Keys!$D$2:$D$800),--(Risk_Rank_Keys!$D$2:$D$800=Risk_Rank_Keys!D20))+1)/2)/COUNT(Risk_Rank_Keys!$D$2:$D$800)) -> 0.78103208 | P20: =AVERAGE(M20:O20) -> 0.86471409 | Q20: =0.4*H20+0.4*I20+0.2*P20 -> 0.49935083 | R20: =PERCENTILE($Q$2:$Q$800,0.75) -> 0.66771572 | S20: =OR(Q20>=R20,AND(B20="CW",COUNT(J20:L20)<3)) -> FALSE | T20: 0.17720405 | U20: 9.7457964 | V20: 0.49935083 | W20: =Q20-V20 -> 0
A21: 2021-02-01 | B21: CW | C21: 31.538393 | D21: =SUMPRODUCT(Risk_Inputs!B21:AJ21,Risk_Coefs!$B$2:$AJ$2) -> -0.53136278 | E21: =1/(1+EXP(-MAX(-25,MIN(25,D21)))) -> 0.3701991 | F21: =SUMPRODUCT(Risk_Inputs!B21:AJ21,Risk_Coefs!$B$3:$AJ$3) -> 9.7479156 | G21: =MAX(0,F21) -> 9.7479156 | H21: =(SUMPRODUCT(--ISNUMBER($E$2:$E$800),--($E$2:$E$800<E21))+(SUMPRODUCT(--ISNUMBER($E$2:$E$800),--($E$2:$E$800=E21))+1)/2)/COUNT($E$2:$E$800) -> 0.87359199 | I21: =(SUMPRODUCT(--ISNUMBER($G$2:$G$800),--($G$2:$G$800<G21))+(SUMPRODUCT(--ISNUMBER($G$2:$G$800),--($G$2:$G$800=G21))+1)/2)/COUNT($G$2:$G$800) -> 0.75969962 | J21: 11.383308 | K21: 1.6230733 | L21: 0.45539468 | M21: =IF(OR(B21="NW",COUNT(Risk_Rank_Keys!B21)=0),0.5,(SUMPRODUCT(--ISNUMBER(Risk_Rank_Keys!$B$2:$B$800),--(Risk_Rank_Keys!$B$2:$B$800<Risk_Rank_Keys!B21))+(SUMPRODUCT(--ISNUMBER(Risk_Rank_Keys!$B$2:$B$800),--(Risk_Rank_Keys!$B$2:$B$800=Risk_Rank_Keys!B21))+1)/2)/COUNT(Risk_Rank_Keys!$B$2:$B$800)) -> 0.56485356 | N21: =IF(OR(B21="NW",COUNT(Risk_Rank_Keys!C21)=0),0.5,(SUMPRODUCT(--ISNUMBER(Risk_Rank_Keys!$C$2:$C$800),--(Risk_Rank_Keys!$C$2:$C$800<Risk_Rank_Keys!C21))+(SUMPRODUCT(--ISNUMBER(Risk_Rank_Keys!$C$2:$C$800),--(Risk_Rank_Keys!$C$2:$C$800=Risk_Rank_Keys!C21))+1)/2)/COUNT(Risk_Rank_Keys!$C$2:$C$800)) -> 0.16596932 | O21: =IF(OR(B21="NW",COUNT(Risk_Rank_Keys!D21)=0),0.5,(SUMPRODUCT(--ISNUMBER(Risk_Rank_Keys!$D$2:$D$800),--(Risk_Rank_Keys!$D$2:$D$800<Risk_Rank_Keys!D21))+(SUMPRODUCT(--ISNUMBER(Risk_Rank_Keys!$D$2:$D$800),--(Risk_Rank_Keys!$D$2:$D$800=Risk_Rank_Keys!D21))+1)/2)/COUNT(Risk_Rank_Keys!$D$2:$D$800)) -> 0.92608089 | P21: =AVERAGE(M21:O21) -> 0.55230126 | Q21: =0.4*H21+0.4*I21+0.2*P21 -> 0.7637769 | R21: =PERCENTILE($Q$2:$Q$800,0.75) -> 0.66771572 | S21: =OR(Q21>=R21,AND(B21="CW",COUNT(J21:L21)<3)) -> TRUE | T21: 0.3701991 | U21: 9.7479156 | V21: 0.7637769 | W21: =Q21-V21 -> 0
A22: 2021-02-03 | B22: CW | C22: 54.112966 | D22: =SUMPRODUCT(Risk_Inputs!B22:AJ22,Risk_Coefs!$B$2:$AJ$2) -> -1.3198278 | E22: =1/(1+EXP(-MAX(-25,MIN(25,D22)))) -> 0.21084695 | F22: =SUMPRODUCT(Risk_Inputs!B22:AJ22,Risk_Coefs!$B$3:$AJ$3) -> 5.3059622 | G22: =MAX(0,F22) -> 5.3059622 | H22: =(SUMPRODUCT(--ISNUMBER($E$2:$E$800),--($E$2:$E$800<E22))+(SUMPRODUCT(--ISNUMBER($E$2:$E$800),--($E$2:$E$800=E22))+1)/2)/COUNT($E$2:$E$800) -> 0.12390488 | I22: =(SUMPRODUCT(--ISNUMBER($G$2:$G$800),--($G$2:$G$800<G22))+(SUMPRODUCT(--ISNUMBER($G$2:$G$800),--($G$2:$G$800=G22))+1)/2)/COUNT($G$2:$G$800) -> 0.17396746 | J22: 35.667554 | K22: 3.1544136 | L22: 0.63597049 | M22: =IF(OR(B22="NW",COUNT(Risk_Rank_Keys!B22)=0),0.5,(SUMPRODUCT(--ISNUMBER(Risk_Rank_Keys!$B$2:$B$800),--(Risk_Rank_Keys!$B$2:$B$800<Risk_Rank_Keys!B22))+(SUMPRODUCT(--ISNUMBER(Risk_Rank_Keys!$B$2:$B$800),--(Risk_Rank_Keys!$B$2:$B$800=Risk_Rank_Keys!B22))+1)/2)/COUNT(Risk_Rank_Keys!$B$2:$B$800)) -> 0.93305439 | N22: =IF(OR(B22="NW",COUNT(Risk_Rank_Keys!C22)=0),0.5,(SUMPRODUCT(--ISNUMBER(Risk_Rank_Keys!$C$2:$C$800),--(Risk_Rank_Keys!$C$2:$C$800<Risk_Rank_Keys!C22))+(SUMPRODUCT(--ISNUMBER(Risk_Rank_Keys!$C$2:$C$800),--(Risk_Rank_Keys!$C$2:$C$800=Risk_Rank_Keys!C22))+1)/2)/COUNT(Risk_Rank_Keys!$C$2:$C$800)) -> 0.48814505 | O22: =IF(OR(B22="NW",COUNT(Risk_Rank_Keys!D22)=0),0.5,(SUMPRODUCT(--ISNUMBER(Risk_Rank_Keys!$D$2:$D$800),--(Risk_Rank_Keys!$D$2:$D$800<Risk_Rank_Keys!D22))+(SUMPRODUCT(--ISNUMBER(Risk_Rank_Keys!$D$2:$D$800),--(Risk_Rank_Keys!$D$2:$D$800=Risk_Rank_Keys!D22))+1)/2)/COUNT(Risk_Rank_Keys!$D$2:$D$800)) -> 0.9818689 | P22: =AVERAGE(M22:O22) -> 0.80102278 | Q22: =0.4*H22+0.4*I22+0.2*P22 -> 0.27935349 | R22: =PERCENTILE($Q$2:$Q$800,0.75) -> 0.66771572 | S22: =OR(Q22>=R22,AND(B22="CW",COUNT(J22:L22)<3)) -> FALSE | T22: 0.21084695 | U22: 5.3059622 | V22: 0.27935349 | W22: =Q22-V22 -> 0
A23: 2021-02-04 | B23: CW | C23: 47.128969 | D23: =SUMPRODUCT(Risk_Inputs!B23:AJ23,Risk_Coefs!$B$2:$AJ$2) -> -0.90374821 | E23: =1/(1+EXP(-MAX(-25,MIN(25,D23)))) -> 0.28828085 | F23: =SUMPRODUCT(Risk_Inputs!B23:AJ23,Risk_Coefs!$B$3:$AJ$3) -> 9.7978301 | G23: =MAX(0,F23) -> 9.7978301 | H23: =(SUMPRODUCT(--ISNUMBER($E$2:$E$800),--($E$2:$E$800<E23))+(SUMPRODUCT(--ISNUMBER($E$2:$E$800),--($E$2:$E$800=E23))+1)/2)/COUNT($E$2:$E$800) -> 0.5106383 | I23: =(SUMPRODUCT(--ISNUMBER($G$2:$G$800),--($G$2:$G$800<G23))+(SUMPRODUCT(--ISNUMBER($G$2:$G$800),--($G$2:$G$800=G23))+1)/2)/COUNT($G$2:$G$800) -> 0.76470588 | J23: 26.100976 | K23: 12.252811 | L23: 0.38774719 | M23: =IF(OR(B23="NW",COUNT(Risk_Rank_Keys!B23)=0),0.5,(SUMPRODUCT(--ISNUMBER(Risk_Rank_Keys!$B$2:$B$800),--(Risk_Rank_Keys!$B$2:$B$800<Risk_Rank_Keys!B23))+(SUMPRODUCT(--ISNUMBER(Risk_Rank_Keys!$B$2:$B$800),--(Risk_Rank_Keys!$B$2:$B$800=Risk_Rank_Keys!B23))+1)/2)/COUNT(Risk_Rank_Keys!$B$2:$B$800)) -> 0.87029289 | N23: =IF(OR(B23="NW",COUNT(Risk_Rank_Keys!C23)=0),0.5,(SUMPRODUCT(--ISNUMBER(Risk_Rank_Keys!$C$2:$C$800),--(Risk_Rank_Keys!$C$2:$C$800<Risk_Rank_Keys!C23))+(SUMPRODUCT(--ISNUMBER(Risk_Rank_Keys!$C$2:$C$800),--(Risk_Rank_Keys!$C$2:$C$800=Risk_Rank_Keys!C23))+1)/2)/COUNT(Risk_Rank_Keys!$C$2:$C$800)) -> 0.90516039 | O23: =IF(OR(B23="NW",COUNT(Risk_Rank_Keys!D23)=0),0.5,(SUMPRODUCT(--ISNUMBER(Risk_Rank_Keys!$D$2:$D$800),--(Risk_Rank_Keys!$D$2:$D$800<Risk_Rank_Keys!D23))+(SUMPRODUCT(--ISNUMBER(Risk_Rank_Keys!$D$2:$D$800),--(Risk_Rank_Keys!$D$2:$D$800=Risk_Rank_Keys!D23))+1)/2)/COUNT(Risk_Rank_Keys!$D$2:$D$800)) -> 0.87168759 | P23: =AVERAGE(M23:O23) -> 0.88238029 | Q23: =0.4*H23+0.4*I23+0.2*P23 -> 0.68661373 | R23: =PERCENTILE($Q$2:$Q$800,0.75) -> 0.66771572 | S23: =OR(Q23>=R23,AND(B23="CW",COUNT(J23:L23)<3)) -> TRUE | T23: 0.28828085 | U23: 9.7978301 | V23: 0.68661373 | W23: =Q23-V23 -> 0
A24: 2021-02-05 | B24: CW | C24: -33.663103 | D24: =SUMPRODUCT(Risk_Inputs!B24:AJ24,Risk_Coefs!$B$2:$AJ$2) -> -1.4679131 | E24: =1/(1+EXP(-MAX(-25,MIN(25,D24)))) -> 0.18726001 | F24: =SUMPRODUCT(Risk_Inputs!B24:AJ24,Risk_Coefs!$B$3:$AJ$3) -> 7.5789464 | G24: =MAX(0,F24) -> 7.5789464 | H24: =(SUMPRODUCT(--ISNUMBER($E$2:$E$800),--($E$2:$E$800<E24))+(SUMPRODUCT(--ISNUMBER($E$2:$E$800),--($E$2:$E$800=E24))+1)/2)/COUNT($E$2:$E$800) -> 0.078848561 | I24: =(SUMPRODUCT(--ISNUMBER($G$2:$G$800),--($G$2:$G$800<G24))+(SUMPRODUCT(--ISNUMBER($G$2:$G$800),--($G$2:$G$800=G24))+1)/2)/COUNT($G$2:$G$800) -> 0.49561952 | J24: 18.371404 | K24: 8.5873433 | L24: 0.61890763 | M24: =IF(OR(B24="NW",COUNT(Risk_Rank_Keys!B24)=0),0.5,(SUMPRODUCT(--ISNUMBER(Risk_Rank_Keys!$B$2:$B$800),--(Risk_Rank_Keys!$B$2:$B$800<Risk_Rank_Keys!B24))+(SUMPRODUCT(--ISNUMBER(Risk_Rank_Keys!$B$2:$B$800),--(Risk_Rank_Keys!$B$2:$B$800=Risk_Rank_Keys!B24))+1)/2)/COUNT(Risk_Rank_Keys!$B$2:$B$800)) -> 0.77126918 | N24: =IF(OR(B24="NW",COUNT(Risk_Rank_Keys!C24)=0),0.5,(SUMPRODUCT(--ISNUMBER(Risk_Rank_Keys!$C$2:$C$800),--(Risk_Rank_Keys!$C$2:$C$800<Risk_Rank_Keys!C24))+(SUMPRODUCT(--ISNUMBER(Risk_Rank_Keys!$C$2:$C$800),--(Risk_Rank_Keys!$C$2:$C$800=Risk_Rank_Keys!C24))+1)/2)/COUNT(Risk_Rank_Keys!$C$2:$C$800)) -> 0.84100418 | O24: =IF(OR(B24="NW",COUNT(Risk_Rank_Keys!D24)=0),0.5,(SUMPRODUCT(--ISNUMBER(Risk_Rank_Keys!$D$2:$D$800),--(Risk_Rank_Keys!$D$2:$D$800<Risk_Rank_Keys!D24))+(SUMPRODUCT(--ISNUMBER(Risk_Rank_Keys!$D$2:$D$800),--(Risk_Rank_Keys!$D$2:$D$800=Risk_Rank_Keys!D24))+1)/2)/COUNT(Risk_Rank_Keys!$D$2:$D$800)) -> 0.9804742 | P24: =AVERAGE(M24:O24) -> 0.86424919 | Q24: =0.4*H24+0.4*I24+0.2*P24 -> 0.40263707 | R24: =PERCENTILE($Q$2:$Q$800,0.75) -> 0.66771572 | S24: =OR(Q24>=R24,AND(B24="CW",COUNT(J24:L24)<3)) -> FALSE | T24: 0.18726001 | U24: 7.5789464 | V24: 0.40263707 | W24: =Q24-V24 -> 0
A25: 2021-02-08 | B25: CW | C25: 57.129349 | D25: =SUMPRODUCT(Risk_Inputs!B25:AJ25,Risk_Coefs!$B$2:$AJ$2) -> -1.1363517 | E25: =1/(1+EXP(-MAX(-25,MIN(25,D25)))) -> 0.24299082 | F25: =SUMPRODUCT(Risk_Inputs!B25:AJ25,Risk_Coefs!$B$3:$AJ$3) -> 9.1953713 | G25: =MAX(0,F25) -> 9.1953713 | H25: =(SUMPRODUCT(--ISNUMBER($E$2:$E$800),--($E$2:$E$800<E25))+(SUMPRODUCT(--ISNUMBER($E$2:$E$800),--($E$2:$E$800=E25))+1)/2)/COUNT($E$2:$E$800) -> 0.23529412 | I25: =(SUMPRODUCT(--ISNUMBER($G$2:$G$800),--($G$2:$G$800<G25))+(SUMPRODUCT(--ISNUMBER($G$2:$G$800),--($G$2:$G$800=G25))+1)/2)/COUNT($G$2:$G$800) -> 0.70212766 | J25: 27.113598 | K25: 6.0065214 | L25: 0.51484469 | M25: =IF(OR(B25="NW",COUNT(Risk_Rank_Keys!B25)=0),0.5,(SUMPRODUCT(--ISNUMBER(Risk_Rank_Keys!$B$2:$B$800),--(Risk_Rank_Keys!$B$2:$B$800<Risk_Rank_Keys!B25))+(SUMPRODUCT(--ISNUMBER(Risk_Rank_Keys!$B$2:$B$800),--(Risk_Rank_Keys!$B$2:$B$800=Risk_Rank_Keys!B25))+1)/2)/COUNT(Risk_Rank_Keys!$B$2:$B$800)) -> 0.88563459 | N25: =IF(OR(B25="NW",COUNT(Risk_Rank_Keys!C25)=0),0.5,(SUMPRODUCT(--ISNUMBER(Risk_Rank_Keys!$C$2:$C$800),--(Risk_Rank_Keys!$C$2:$C$800<Risk_Rank_Keys!C25))+(SUMPRODUCT(--ISNUMBER(Risk_Rank_Keys!$C$2:$C$800),--(Risk_Rank_Keys!$C$2:$C$800=Risk_Rank_Keys!C25))+1)/2)/COUNT(Risk_Rank_Keys!$C$2:$C$800)) -> 0.74476987 | O25: =IF(OR(B25="NW",COUNT(Risk_Rank_Keys!D25)=0),0.5,(SUMPRODUCT(--ISNUMBER(Risk_Rank_Keys!$D$2:$D$800),--(Risk_Rank_Keys!$D$2:$D$800<Risk_Rank_Keys!D25))+(SUMPRODUCT(--ISNUMBER(Risk_Rank_Keys!$D$2:$D$800),--(Risk_Rank_Keys!$D$2:$D$800=Risk_Rank_Keys!D25))+1)/2)/COUNT(Risk_Rank_Keys!$D$2:$D$800)) -> 0.9595537 | P25: =AVERAGE(M25:O25) -> 0.86331939 | Q25: =0.4*H25+0.4*I25+0.2*P25 -> 0.54763259 | R25: =PERCENTILE($Q$2:$Q$800,0.75) -> 0.66771572 | S25: =OR(Q25>=R25,AND(B25="CW",COUNT(J25:L25)<3)) -> FALSE | T25: 0.24299082 | U25: 9.1953713 | V25: 0.54763259 | W25: =Q25-V25 -> 0
