Workbook

Sheet Summary
A1: GammaShort - history summary (research results on the share)
A2: 01-Jan-2021 to 19-Aug-2026, 1373 days. Combined book = current-week + next-week legs.
A4: Notional per trade (Rs) <- change this | B4: 112612500 | C4: default = 77 lots x 65 x index 22,500
A5: Rupees per 1 normalised Rs | B5: =B4/25000 | C5: the files are sized at Rs 25,000 notional per trade
A7: Metric | B7: Normalised Rs | C7: Rupees at the notional above | D7: Note
A8: Net PnL (profit) | B8: 10600.25 | C8: =B8*$B$5
A9: Max drawdown | B9: 162.11 | C9: =B9*$B$5 | D9: 28-Feb-2025 peak to 24-Mar-2025 trough
A10: PnL / max drawdown | B10: 65.39 | D10: size-independent
A11: Days in the history | B11: 1373
A12: Days with a trade | B12: 1003 | D12: days with non-zero PnL
A13: Winning trades % | B13: 68.69
A14: Average per trade | B14: 10.57 | C14: =B14*$B$5
A15: Average winning trade | B15: 26.36 | C15: =B15*$B$5
A16: Average losing trade | B16: -24.09 | C16: =B16*$B$5
A17: Best day | B17: 279.44 | C17: =B17*$B$5 | D17: 24-Feb-2021
A18: Worst day | B18: -61.28 | C18: =B18*$B$5 | D18: 29-Feb-2024
A19: Average PnL per year | B19: 1883.14 | C19: =B19*$B$5 | D19: calendar years in the history
A21: Sizing table
A22: Size | B22: Notional (Rs) | C22: Net PnL (Rs) | D22: Max drawdown (Rs) | E22: Worst day (Rs) | F22: Avg per trade (Rs)
A23: 1 lot (65) | B23: 1462500 | C23: =B23/25000*10600.254014 | D23: =B23/25000*162.107010 | E23: =B23/25000*-61.279315 | F23: =B23/25000*10.568548
A24: 10 lots | B24: 14625000 | C24: =B24/25000*10600.254014 | D24: =B24/25000*162.107010 | E24: =B24/25000*-61.279315 | F24: =B24/25000*10.568548
A25: 25 lots | B25: 36562500 | C25: =B25/25000*10600.254014 | D25: =B25/25000*162.107010 | E25: =B25/25000*-61.279315 | F25: =B25/25000*10.568548
A26: 50 lots | B26: 73125000 | C26: =B26/25000*10600.254014 | D26: =B26/25000*162.107010 | E26: =B26/25000*-61.279315 | F26: =B26/25000*10.568548
A27: 77 lots (live size) | B27: 112612500 | C27: =B27/25000*10600.254014 | D27: =B27/25000*162.107010 | E27: =B27/25000*-61.279315 | F27: =B27/25000*10.568548
A28: 100 lots | B28: 146250000 | C28: =B28/25000*10600.254014 | D28: =B28/25000*162.107010 | E28: =B28/25000*-61.279315 | F28: =B28/25000*10.568548
A29: 150 lots | B29: 219375000 | C29: =B29/25000*10600.254014 | D29: =B29/25000*162.107010 | E29: =B29/25000*-61.279315 | F29: =B29/25000*10.568548
A31: How sizing works: every backtest trade is Rs 25,000 of notional, whatever the index level. Rupees = normalised x notional / 25,000.
A32: Lots are converted at index 22,500 (1 lot = Rs 1,462,500 notional). A fixed number of lots was a smaller notional when the index was lower,
A33: so 'lots' columns describe a constant-notional book equal to that many lots today, not a fixed lot count through history.
A34: Max drawdown is on the daily closing equity (starting at 0), the same definition as the backtest script.
A35: Costs are already inside these numbers (entry slippage and hedge cost as modelled by the research). Brokerage, STT and exchange charges are not.
A36: Source: combined_book_daily.csv dated 02-Sep-2026 on the share. It predates the 17-Sep 'no-roll' re-base and the round-52 script in this folder,
A37: whose header quotes 10,640.5 / MDD 144.4 over 1,379 days. This workbook reports the saved file, not a new run of the script.
A38: Daily sheet, Leg column: CW = the day's PnL equals the current-week file; NW = it differs and the day is in the next-week file;
A39: n/a = it differs and the saved files do not say which leg or entry produced it.

Sheet By_FY
A1: Financial year | B1: Days | C1: Trades | D1: Win % | E1: Net PnL (norm) | F1: Max DD (norm) | G1: Worst day (norm) | H1: Net PnL (Rs) | I1: Max DD (Rs) | J1: Worst day (Rs)
A2: FY20-21 | B2: 61 | C2: 56 | D2: 66.1 | E2: 997.4 | F2: 97.5 | G2: -46 | H2: =E2*Summary!$B$5 | I2: =F2*Summary!$B$5 | J2: =G2*Summary!$B$5
A3: FY21-22 | B3: 245 | C3: 205 | D3: 70.2 | E3: 2415.2 | F3: 136 | G3: -47.6 | H3: =E3*Summary!$B$5 | I3: =F3*Summary!$B$5 | J3: =G3*Summary!$B$5
A4: FY22-23 | B4: 248 | C4: 192 | D4: 64.1 | E4: 1607.6 | F4: 136.6 | G4: -51.2 | H4: =E4*Summary!$B$5 | I4: =F4*Summary!$B$5 | J4: =G4*Summary!$B$5
A5: FY23-24 | B5: 244 | C5: 157 | D5: 68.8 | E5: 985 | F5: 107.9 | G5: -61.3 | H5: =E5*Summary!$B$5 | I5: =F5*Summary!$B$5 | J5: =G5*Summary!$B$5
A6: FY24-25 | B6: 240 | C6: 187 | D6: 69.5 | E6: 2116.7 | F6: 162.1 | G6: -49.9 | H6: =E6*Summary!$B$5 | I6: =F6*Summary!$B$5 | J6: =G6*Summary!$B$5
A7: FY25-26 | B7: 241 | C7: 144 | D7: 69.4 | E7: 1742.4 | F7: 116.8 | G7: -48.6 | H7: =E7*Summary!$B$5 | I7: =F7*Summary!$B$5 | J7: =G7*Summary!$B$5
A8: FY26-27 | B8: 94 | C8: 62 | D8: 75.8 | E8: 735.9 | F8: 57 | G8: -43.5 | H8: =E8*Summary!$B$5 | I8: =F8*Summary!$B$5 | J8: =G8*Summary!$B$5

Sheet By_Month
A1: Month | B1: Trades | C1: Win % | D1: Net PnL (norm) | E1: Worst day (norm) | F1: Net PnL (Rs) | G1: Worst day (Rs)
A2: 2021-01 | B2: 20 | C2: 55 | D2: 26 | E2: -45.7 | F2: =D2*Summary!$B$5 | G2: =E2*Summary!$B$5
A3: 2021-02 | B3: 18 | C3: 72.2 | D3: 514.4 | E3: -46 | F3: =D3*Summary!$B$5 | G3: =E3*Summary!$B$5
A4: 2021-03 | B4: 18 | C4: 72.2 | D4: 457 | E4: -39.6 | F4: =D4*Summary!$B$5 | G4: =E4*Summary!$B$5
A5: 2021-04 | B5: 17 | C5: 70.6 | D5: 206.5 | E5: -47.6 | F5: =D5*Summary!$B$5 | G5: =E5*Summary!$B$5
A6: 2021-05 | B6: 15 | C6: 80 | D6: 323.6 | E6: -40 | F6: =D6*Summary!$B$5 | G6: =E6*Summary!$B$5
A7: 2021-06 | B7: 20 | C7: 75 | D7: 222.2 | E7: -39.2 | F7: =D7*Summary!$B$5 | G7: =E7*Summary!$B$5
A8: 2021-07 | B8: 15 | C8: 80 | D8: 126.9 | E8: -40.2 | F8: =D8*Summary!$B$5 | G8: =E8*Summary!$B$5
A9: 2021-08 | B9: 16 | C9: 56.2 | D9: 63.2 | E9: -38 | F9: =D9*Summary!$B$5 | G9: =E9*Summary!$B$5
A10: 2021-09 | B10: 14 | C10: 92.9 | D10: 234 | E10: -46.7 | F10: =D10*Summary!$B$5 | G10: =E10*Summary!$B$5
A11: 2021-10 | B11: 19 | C11: 68.4 | D11: 186.6 | E11: -38.8 | F11: =D11*Summary!$B$5 | G11: =E11*Summary!$B$5
A12: 2021-11 | B12: 16 | C12: 62.5 | D12: 53 | E12: -47 | F12: =D12*Summary!$B$5 | G12: =E12*Summary!$B$5
A13: 2021-12 | B13: 21 | C13: 66.7 | D13: 328 | E13: -41 | F13: =D13*Summary!$B$5 | G13: =E13*Summary!$B$5
... A69: 2026-08 | B69: 9 | C69: 77.8 | D69: 167 | E69: -21.7 | F69: =D69*Summary!$B$5 | G69: =E69*Summary!$B$5

Sheet CW_by_DTE_and_entry
A1: Group | B1: Trades | C1: Win % | D1: Net PnL (norm) | E1: Avg per trade (norm) | F1: Worst (norm) | G1: Net PnL (Rs) | H1: Worst (Rs)
A2: By days to expiry (1 = expiry day)
A3: DTE 1 | B3: 212 | C3: 69.8 | D3: 3540.9 | E3: 16.7 | F3: -61.3 | G3: =D3*Summary!$B$5 | H3: =F3*Summary!$B$5
A4: DTE 2 | B4: 204 | C4: 64.2 | D4: 1548.3 | E4: 7.59 | F4: -46.6 | G4: =D4*Summary!$B$5 | H4: =F4*Summary!$B$5
A5: DTE 3 | B5: 154 | C5: 71.4 | D5: 1910.1 | E5: 12.4 | F5: -46.7 | G5: =D5*Summary!$B$5 | H5: =F5*Summary!$B$5
A6: DTE 4 | B6: 147 | C6: 66.7 | D6: 1151.9 | E6: 7.84 | F6: -48.5 | G6: =D6*Summary!$B$5 | H6: =F6*Summary!$B$5
A7: DTE 5 | B7: 25 | C7: 84 | D7: 397.4 | E7: 15.9 | F7: -38.1 | G7: =D7*Summary!$B$5 | H7: =F7*Summary!$B$5
A8: DTE 6 | B8: 117 | C8: 76.1 | D8: 1440.9 | E8: 12.32 | F8: -48.6 | G8: =D8*Summary!$B$5 | H8: =F8*Summary!$B$5
A10: By entry time
A11: 09:16 | B11: 188 | C11: 80.3 | D11: 4806.4 | E11: 25.57 | F11: -49.9 | G11: =D11*Summary!$B$5 | H11: =F11*Summary!$B$5
A12: 09:17 | B12: 191 | C12: 75.4 | D12: 2892.5 | E12: 15.14 | F12: -61.3 | G12: =D12*Summary!$B$5 | H12: =F12*Summary!$B$5
A13: 09:18 | B13: 430 | C13: 63.3 | D13: 1888.8 | E13: 4.39 | F13: -59.7 | G13: =D13*Summary!$B$5 | H13: =F13*Summary!$B$5
A14: 09:19 | B14: 8 | C14: 37.5 | D14: -40.2 | E14: -5.02 | F14: -37.9 | G14: =D14*Summary!$B$5 | H14: =F14*Summary!$B$5
A15: 09:20-09:59 | B15: 14 | C15: 50 | D15: 104 | E15: 7.43 | F15: -38.7 | G15: =D15*Summary!$B$5 | H15: =F15*Summary!$B$5
A16: 10:00 onwards | B16: 28 | C16: 71.4 | D16: 337.9 | E16: 12.07 | F16: -48.5 | G16: =D16*Summary!$B$5 | H16: =F16*Summary!$B$5
A18: Source: ps1_daily_walk.csv (current-week leg only, before the next-week leg replaces some days).

Sheet Drawdowns
A1: Rank | B1: Peak date | C1: Trough date | D1: Recovered | E1: Days peak to trough | F1: Depth (norm) | G1: Depth (Rs)
A2: 1 | B2: 45716 | C2: 45740 | D2: 45756 | E2: 24 | F2: 162.1 | G2: =F2*Summary!$B$5
A3: 2 | B3: 44904 | C3: 44917 | D3: 44949 | E3: 13 | F3: 136.6 | G3: =F3*Summary!$B$5
A4: 3 | B4: 44588 | C4: 44609 | D4: 44614 | E4: 21 | F4: 136 | G4: =F4*Summary!$B$5
A5: 4 | B5: 44791 | C5: 44825 | D5: 44834 | E5: 34 | F5: 131.3 | G5: =F5*Summary!$B$5
A6: 5 | B6: 45674 | C6: 45686 | D6: 45688 | E6: 12 | F6: 127.2 | G6: =F6*Summary!$B$5
A7: 6 | B7: 45799 | C7: 45804 | D7: 45806 | E7: 5 | F7: 116.8 | G7: =F7*Summary!$B$5
A8: 7 | B8: 45349 | C8: 45351 | D8: 45358 | E8: 2 | F8: 107.9 | G8: =F8*Summary!$B$5
A9: 8 | B9: 44540 | C9: 44545 | D9: 44553 | E9: 5 | F9: 100.9 | G9: =F9*Summary!$B$5
A10: 9 | B10: 44995 | C10: 45009 | D10: 45035 | E10: 14 | F10: 97.8 | G10: =F10*Summary!$B$5
A11: 10 | B11: 44217 | C11: 44225 | D11: 44231 | E11: 8 | F11: 97.5 | G11: =F11*Summary!$B$5
A12: 11 | B12: 44200 | C12: 44207 | D12: 44216 | E12: 7 | F12: 95.6 | G12: =F12*Summary!$B$5
A13: 12 | B13: 44950 | C13: 44956 | D13: 44964 | E13: 6 | F13: 92.6 | G13: =F13*Summary!$B$5
... A16: 15 | B16: 46093 | C16: 46104 | D16: 46108 | E16: 11 | F16: 85 | G16: =F16*Summary!$B$5

Sheet Daily
A1: Date | B1: FY | C1: Leg | D1: CW entry | E1: DTE | F1: PnL (norm) | G1: Cum PnL (norm) | H1: Drawdown (norm) | I1: PnL (Rs) | J1: Cum PnL (Rs) | K1: Drawdown (Rs)
A2: 44197 | B2: FY20-21 | C2: CW | D2: 09:17 | E2: 6 | F2: 34.79 | G2: 34.79 | H2: 0 | I2: =F2*Summary!$B$5 | J2: =G2*Summary!$B$5 | K2: =H2*Summary!$B$5
A3: 44200 | B3: FY20-21 | C3: CW | D3: 11:01 | E3: 4 | F3: 47.29 | G3: 82.08 | H3: 0 | I3: =F3*Summary!$B$5 | J3: =G3*Summary!$B$5 | K3: =H3*Summary!$B$5
A4: 44201 | B4: FY20-21 | C4: CW | D4: 09:18 | E4: 3 | F4: -13.77 | G4: 68.3 | H4: -13.77 | I4: =F4*Summary!$B$5 | J4: =G4*Summary!$B$5 | K4: =H4*Summary!$B$5
A5: 44202 | B5: FY20-21 | C5: CW | D5: 09:18 | E5: 2 | F5: -42.27 | G5: 26.03 | H5: -56.04 | I5: =F5*Summary!$B$5 | J5: =G5*Summary!$B$5 | K5: =H5*Summary!$B$5
A6: 44203 | B6: FY20-21 | C6: CW | D6: 09:18 | E6: 1 | F6: 40.43 | G6: 66.46 | H6: -15.61 | I6: =F6*Summary!$B$5 | J6: =G6*Summary!$B$5 | K6: =H6*Summary!$B$5
A7: 44204 | B7: FY20-21 | C7: n/a | E7: 0 | F7: -42.03 | G7: 24.44 | H7: -57.64 | I7: =F7*Summary!$B$5 | J7: =G7*Summary!$B$5 | K7: =H7*Summary!$B$5
A8: 44207 | B8: FY20-21 | C8: CW | D8: 09:19 | E8: 4 | F8: -37.92 | G8: -13.49 | H8: -95.56 | I8: =F8*Summary!$B$5 | J8: =G8*Summary!$B$5 | K8: =H8*Summary!$B$5
A9: 44208 | B9: FY20-21 | C9: CW | D9: 09:17 | E9: 3 | F9: 12.98 | G9: -0.51 | H9: -82.58 | I9: =F9*Summary!$B$5 | J9: =G9*Summary!$B$5 | K9: =H9*Summary!$B$5
A10: 44209 | B10: FY20-21 | C10: CW | D10: 09:17 | E10: 2 | F10: 29.87 | G10: 29.36 | H10: -52.72 | I10: =F10*Summary!$B$5 | J10: =G10*Summary!$B$5 | K10: =H10*Summary!$B$5
A11: 44210 | B11: FY20-21 | C11: CW | D11: 09:17 | E11: 1 | F11: 11.84 | G11: 41.2 | H11: -40.88 | I11: =F11*Summary!$B$5 | J11: =G11*Summary!$B$5 | K11: =H11*Summary!$B$5
A12: 44211 | B12: FY20-21 | C12: CW | D12: 09:17 | E12: 6 | F12: -45.13 | G12: -3.94 | H12: -86.01 | I12: =F12*Summary!$B$5 | J12: =G12*Summary!$B$5 | K12: =H12*Summary!$B$5
A13: 44214 | B13: FY20-21 | C13: CW | D13: 09:18 | E13: 4 | F13: 8.58 | G13: 4.64 | H13: -77.43 | I13: =F13*Summary!$B$5 | J13: =G13*Summary!$B$5 | K13: =H13*Summary!$B$5
A14: 44215 | B14: FY20-21 | C14: CW | D14: 09:16 | E14: 3 | F14: 43.05 | G14: 47.7 | H14: -34.38 | I14: =F14*Summary!$B$5 | J14: =G14*Summary!$B$5 | K14: =H14*Summary!$B$5
A15: 44216 | B15: FY20-21 | C15: CW | D15: 09:17 | E15: 2 | F15: 53.99 | G15: 101.69 | H15: 0 | I15: =F15*Summary!$B$5 | J15: =G15*Summary!$B$5 | K15: =H15*Summary!$B$5
A16: 44217 | B16: FY20-21 | C16: CW | D16: 09:16 | E16: 1 | F16: 21.77 | G16: 123.46 | H16: 0 | I16: =F16*Summary!$B$5 | J16: =G16*Summary!$B$5 | K16: =H16*Summary!$B$5
A17: 44218 | B17: FY20-21 | C17: CW | D17: 11:18 | E17: 6 | F17: -35.66 | G17: 87.8 | H17: -35.66 | I17: =F17*Summary!$B$5 | J17: =G17*Summary!$B$5 | K17: =H17*Summary!$B$5
A18: 44221 | B18: FY20-21 | C18: n/a | E18: 4 | F18: -40.16 | G18: 47.64 | H18: -75.82 | I18: =F18*Summary!$B$5 | J18: =G18*Summary!$B$5 | K18: =H18*Summary!$B$5
A19: 44223 | B19: FY20-21 | C19: CW | D19: 09:16 | E19: 2 | F19: 67.06 | G19: 114.7 | H19: -8.77 | I19: =F19*Summary!$B$5 | J19: =G19*Summary!$B$5 | K19: =H19*Summary!$B$5
A20: 44224 | B20: FY20-21 | C20: CW | D20: 09:16 | E20: 1 | F20: -45.7 | G20: 69 | H20: -54.47 | I20: =F20*Summary!$B$5 | J20: =G20*Summary!$B$5 | K20: =H20*Summary!$B$5
A21: 44225 | B21: FY20-21 | C21: CW | D21: 09:16 | E21: 6 | F21: -42.99 | G21: 26 | H21: -97.46 | I21: =F21*Summary!$B$5 | J21: =G21*Summary!$B$5 | K21: =H21*Summary!$B$5
A22: 44228 | B22: FY20-21 | C22: CW | D22: 09:18 | E22: 4 | F22: 31.53 | G22: 57.53 | H22: -65.93 | I22: =F22*Summary!$B$5 | J22: =G22*Summary!$B$5 | K22: =H22*Summary!$B$5
A23: 44229 | B23: FY20-21 | E23: 0 | F23: 0 | G23: 57.53 | H23: -65.93 | I23: =F23*Summary!$B$5 | J23: =G23*Summary!$B$5 | K23: =H23*Summary!$B$5
A24: 44230 | B24: FY20-21 | C24: CW | D24: 09:18 | E24: 2 | F24: 8.84 | G24: 66.37 | H24: -57.09 | I24: =F24*Summary!$B$5 | J24: =G24*Summary!$B$5 | K24: =H24*Summary!$B$5
A25: 44231 | B25: FY20-21 | C25: CW | D25: 09:16 | E25: 1 | F25: 71.26 | G25: 137.63 | H25: 0 | I25: =F25*Summary!$B$5 | J25: =G25*Summary!$B$5 | K25: =H25*Summary!$B$5
A26: 44232 | B26: FY20-21 | C26: CW | D26: 09:17 | E26: 6 | F26: -36.53 | G26: 101.1 | H26: -36.53 | I26: =F26*Summary!$B$5 | J26: =G26*Summary!$B$5 | K26: =H26*Summary!$B$5
A27: 44235 | B27: FY20-21 | C27: CW | D27: 09:16 | E27: 4 | F27: 57.13 | G27: 158.23 | H27: 0 | I27: =F27*Summary!$B$5 | J27: =G27*Summary!$B$5 | K27: =H27*Summary!$B$5
A28: 44236 | B28: FY20-21 | C28: CW | D28: 09:16 | E28: 3 | F28: 17.6 | G28: 175.83 | H28: 0 | I28: =F28*Summary!$B$5 | J28: =G28*Summary!$B$5 | K28: =H28*Summary!$B$5
A29: 44237 | B29: FY20-21 | C29: NW | E29: 2 | F29: 42.73 | G29: 218.56 | H29: 0 | I29: =F29*Summary!$B$5 | J29: =G29*Summary!$B$5 | K29: =H29*Summary!$B$5
A30: 44238 | B30: FY20-21 | C30: CW | D30: 09:16 | E30: 1 | F30: 66.39 | G30: 284.95 | H30: 0 | I30: =F30*Summary!$B$5 | J30: =G30*Summary!$B$5 | K30: =H30*Summary!$B$5
A31: 44239 | B31: FY20-21 | C31: CW | D31: 09:18 | E31: 6 | F31: 35.96 | G31: 320.91 | H31: 0 | I31: =F31*Summary!$B$5 | J31: =G31*Summary!$B$5 | K31: =H31*Summary!$B$5
A32: 44242 | B32: FY20-21 | E32: 0 | F32: 0 | G32: 320.91 | H32: 0 | I32: =F32*Summary!$B$5 | J32: =G32*Summary!$B$5 | K32: =H32*Summary!$B$5
A33: 44243 | B33: FY20-21 | C33: CW | D33: 09:18 | E33: 3 | F33: 6.29 | G33: 327.2 | H33: 0 | I33: =F33*Summary!$B$5 | J33: =G33*Summary!$B$5 | K33: =H33*Summary!$B$5
A34: 44244 | B34: FY20-21 | C34: CW | D34: 09:17 | E34: 2 | F34: -46.02 | G34: 281.18 | H34: -46.02 | I34: =F34*Summary!$B$5 | J34: =G34*Summary!$B$5 | K34: =H34*Summary!$B$5
A35: 44245 | B35: FY20-21 | C35: CW | D35: 09:17 | E35: 1 | F35: 49.19 | G35: 330.37 | H35: 0 | I35: =F35*Summary!$B$5 | J35: =G35*Summary!$B$5 | K35: =H35*Summary!$B$5
A36: 44246 | B36: FY20-21 | C36: CW | D36: 09:16 | E36: 6 | F36: -32.72 | G36: 297.66 | H36: -32.72 | I36: =F36*Summary!$B$5 | J36: =G36*Summary!$B$5 | K36: =H36*Summary!$B$5
A37: 44249 | B37: FY20-21 | C37: CW | D37: 09:16 | E37: 4 | F37: -37.26 | G37: 260.39 | H37: -69.98 | I37: =F37*Summary!$B$5 | J37: =G37*Summary!$B$5 | K37: =H37*Summary!$B$5
A38: 44250 | B38: FY20-21 | C38: n/a | E38: 3 | F38: 9.51 | G38: 269.91 | H38: -60.47 | I38: =F38*Summary!$B$5 | J38: =G38*Summary!$B$5 | K38: =H38*Summary!$B$5
A39: 44251 | B39: FY20-21 | C39: CW | D39: 09:16 | E39: 2 | F39: 279.44 | G39: 549.34 | H39: 0 | I39: =F39*Summary!$B$5 | J39: =G39*Summary!$B$5 | K39: =H39*Summary!$B$5
A40: 44252 | B40: FY20-21 | C40: CW | D40: 09:16 | E40: 1 | F40: 28.39 | G40: 577.73 | H40: 0 | I40: =F40*Summary!$B$5 | J40: =G40*Summary!$B$5 | K40: =H40*Summary!$B$5
...
